Workbook

Sheet Plant, Month & PO Defect Analys
B1: ERC Inspection Details
A2: Firm Name | B2: Month | C2: PO Number /Date | D2: Zonal Railway (Purchaser) | E2: Consignee Details | F2: Inspected (Nos.) | G2: Acceptance (Nos.) | H2: % Acceptance | I2: Rejection (Nos.) | J2: % Rejection | K2: Visual (Sheared Edges, Surface Defects) | L2: ="%"&K2 -> %Visual (Sheared Edges, Surface Defects) | M2: Dimensional | N2: ="%"&M2 -> %Dimensional | O2: Cut bar length | P2: ="%"&O2 -> %Cut bar length | Q2: Cut Bar diameter | R2: ="%"&Q2 -> %Cut Bar diameter | S2: Turning length | T2: ="%"&S2 -> %Turning length | U2: Turning Bar Diameter | V2: ="%"&U2 -> %Turning Bar Diameter | W2: Flat Bearing Area | X2: ="%"&W2 -> %Flat Bearing Area | Y2: Application & Deflection test | Z2: ="%"&Y2 -> %Application & Deflection test | AA2: Chemical Composition | AB2: ="%"&AA2 -> %Chemical Composition | AC2: Toe load | AD2: ="%"&AC2 -> %Toe load | AE2: Hardness | AF2: ="%"&AE2 -> %Hardness | AG2: Microstructure | AH2: ="%"&AG2 -> %Microstructure | AI2: Grain size | AJ2: ="%"&AI2 -> %Grain size | AK2: Depth of Decarburization | AL2: ="%"&AK2 -> %Depth of Decarburization | AM2: Inclusion rating | AN2: ="%"&AM2 -> %Inclusion rating | AO2: MPI | AP2: ="%"&AO2 -> %MPI | AQ2: Forging defect | AR2: ="%"&AQ2 -> %Forging defect | AS2: Marking | AT2: ="%"&AS2 -> %Marking | AU2: Embossing Die Impression / Failure | AV2: ="%"&AU2 -> %Embossing Die Impression / Failure | AW2: Other (less weight) | AX2: ="%"&AW2 -> %Other (less weight)
A3: ERIO AMBE FASTNERS PVT.LTD. Patna Bihar | B3: December 2025 | C3: NO PRODUCTION | H3: =G3/F3 -> #DIV/0! | J3: =I3/F3 -> #DIV/0! | L3: =K3/F3 -> #DIV/0! | N3: =M3/F3 -> #DIV/0! | P3: =O3/F3 -> #DIV/0! | R3: =Q3/F3 -> #DIV/0! | T3: =S3/F3 -> #DIV/0! | V3: =U3/F3 -> #DIV/0! | X3: =W3/F3 -> #DIV/0! | Z3: =Y3/F3 -> #DIV/0! | AB3: =AA3/F3 -> #DIV/0! | AD3: =AC3/F3 -> #DIV/0! | AF3: =AE3/F3 -> #DIV/0! | AH3: =AG3/F3 -> #DIV/0! | AJ3: =AI3/F3 -> #DIV/0! | AL3: =AK3/F3 -> #DIV/0! | AN3: =AM3/F3 -> #DIV/0! | AP3: =AO3/F3 -> #DIV/0! | AR3: =AQ3/F3 -> #DIV/0! | AT3: =AS3/F3 -> #DIV/0! | AV3: =AU3/F3 -> #DIV/0! | AX3: =AW3/F3 -> #DIV/0!
A4: ERIO AMBE FASTNERS PVT.LTD. Patna Bihar | B4: Jan 2026 | C4: NO PRODUCTION | H4: =G4/F4 -> #DIV/0! | J4: =I4/F4 -> #DIV/0! | L4: =K4/F4 -> #DIV/0! | N4: =M4/F4 -> #DIV/0! | P4: =O4/F4 -> #DIV/0! | R4: =Q4/F4 -> #DIV/0! | T4: =S4/F4 -> #DIV/0! | V4: =U4/F4 -> #DIV/0! | X4: =W4/F4 -> #DIV/0! | Z4: =Y4/F4 -> #DIV/0! | AB4: =AA4/F4 -> #DIV/0! | AD4: =AC4/F4 -> #DIV/0! | AF4: =AE4/F4 -> #DIV/0! | AH4: =AG4/F4 -> #DIV/0! | AJ4: =AI4/F4 -> #DIV/0! | AL4: =AK4/F4 -> #DIV/0! | AN4: =AM4/F4 -> #DIV/0! | AP4: =AO4/F4 -> #DIV/0! | AR4: =AQ4/F4 -> #DIV/0! | AT4: =AS4/F4 -> #DIV/0! | AV4: =AU4/F4 -> #DIV/0! | AX4: =AW4/F4 -> #DIV/0! | AZ4: =AY4-I4 -> 0
A5: ERIO CALCUTTA SPRINGS LTD. Howrah West Bengal | B5: December 2025 | C5: 07254988202255 Dt. 14.06.2025 | D5: East Central | E5: ECR | F5: 57229 | G5: 56431 | H5: =G5/F5 -> 0.98605602 | I5: 798 | J5: =I5/F5 -> 0.013943979 | K5: 0 | L5: =K5/F5 -> 0 | M5: 80 | N5: =M5/F5 -> 0.0013978927 | O5: 101 | P5: =O5/F5 -> 0.0017648395 | R5: =Q5/F5 -> 0 | S5: 54 | T5: =S5/F5 -> 0.00094357756 | U5: 36 | V5: =U5/F5 -> 0.0006290517 | W5: 2 | X5: =W5/F5 -> 3.4947317e-05 | Z5: =Y5/F5 -> 0 | AB5: =AA5/F5 -> 0 | AC5: 36 | AD5: =AC5/F5 -> 0.0006290517 | AE5: 23 | AF5: =AE5/F5 -> 0.00040189414 | AH5: =AG5/F5 -> 0 | AJ5: =AI5/F5 -> 0 | AL5: =AK5/F5 -> 0 | AN5: =AM5/F5 -> 0 | AO5: 13 | AP5: =AO5/F5 -> 0.00022715756 | AQ5: 180 | AR5: =AQ5/F5 -> 0.0031452585 | AT5: =AS5/F5 -> 0 | AU5: 220 | AV5: =AU5/F5 -> 0.0038442049 | AW5: 53 | AX5: =AW5/F5 -> 0.0009261039
A6: ERIO CALCUTTA SPRINGS LTD. Howrah West Bengal | B6: December 2025 | C6: 61245413103216 dated 24.06.2025 | D6: North East Frontier | E6: NFR | F6: 113857 | G6: 113598 | H6: =G6/F6 -> 0.99772522 | I6: 259 | J6: =I6/F6 -> 0.0022747833 | K6: 0 | L6: =K6/F6 -> 0 | M6: 8 | N6: =M6/F6 -> 7.0263576e-05 | O6: 55 | P6: =O6/F6 -> 0.00048306209 | R6: =Q6/F6 -> 0 | S6: 28 | T6: =S6/F6 -> 0.00024592252 | U6: 0 | V6: =U6/F6 -> 0 | W6: 0 | X6: =W6/F6 -> 0 | Z6: =Y6/F6 -> 0 | AB6: =AA6/F6 -> 0 | AC6: 21 | AD6: =AC6/F6 -> 0.00018444189 | AE6: 19 | AF6: =AE6/F6 -> 0.00016687599 | AH6: =AG6/F6 -> 0 | AJ6: =AI6/F6 -> 0 | AL6: =AK6/F6 -> 0 | AN6: =AM6/F6 -> 0 | AO6: 10 | AP6: =AO6/F6 -> 8.782947e-05 | AQ6: 43 | AR6: =AQ6/F6 -> 0.00037766672 | AT6: =AS6/F6 -> 0 | AU6: 51 | AV6: =AU6/F6 -> 0.0004479303 | AW6: 24 | AX6: =AW6/F6 -> 0.00021079073
A7: ERIO CALCUTTA SPRINGS LTD. Howrah West Bengal | B7: December 2025 | C7: 06255112102398 dated 06.08.2025 | D7: East Coast | E7: ECoR | F7: 146606 | G7: 145018 | H7: =G7/F7 -> 0.98916825 | I7: 1588 | J7: =I7/F7 -> 0.010831753 | K7: 0 | L7: =K7/F7 -> 0 | M7: 240 | N7: =M7/F7 -> 0.0016370408 | O7: 267 | P7: =O7/F7 -> 0.0018212079 | R7: =Q7/F7 -> 0 | S7: 150 | T7: =S7/F7 -> 0.0010231505 | U7: 13 | V7: =U7/F7 -> 8.8673042e-05 | W7: 0 | X7: =W7/F7 -> 0 | Z7: =Y7/F7 -> 0 | AB7: =AA7/F7 -> 0 | AC7: 34 | AD7: =AC7/F7 -> 0.00023191411 | AE7: 55 | AF7: =AE7/F7 -> 0.00037515518 | AH7: =AG7/F7 -> 0 | AJ7: =AI7/F7 -> 0 | AL7: =AK7/F7 -> 0 | AN7: =AM7/F7 -> 0 | AO7: 26 | AP7: =AO7/F7 -> 0.00017734608 | AQ7: 261 | AR7: =AQ7/F7 -> 0.0017802818 | AT7: =AS7/F7 -> 0 | AU7: 376 | AV7: =AU7/F7 -> 0.0025646972 | AW7: 166 | AX7: =AW7/F7 -> 0.0011322865
A8: ERIO CALCUTTA SPRINGS LTD. Howrah West Bengal | B8: December 2025 | C8: 61255131105052 Dt. 19.09.2025 | D8: North East Frontier | E8: NFR | F8: 57357 | G8: 57029 | H8: =G8/F8 -> 0.99428143 | I8: 328 | J8: =I8/F8 -> 0.0057185697 | K8: 10 | L8: =K8/F8 -> 0.00017434664 | M8: 66 | N8: =M8/F8 -> 0.0011506878 | O8: 35 | P8: =O8/F8 -> 0.00061021323 | R8: =Q8/F8 -> 0 | S8: 30 | T8: =S8/F8 -> 0.00052303991 | U8: 0 | V8: =U8/F8 -> 0 | W8: 0 | X8: =W8/F8 -> 0 | Z8: =Y8/F8 -> 0 | AB8: =AA8/F8 -> 0 | AC8: 14 | AD8: =AC8/F8 -> 0.00024408529 | AE8: 21 | AF8: =AE8/F8 -> 0.00036612794 | AH8: =AG8/F8 -> 0 | AJ8: =AI8/F8 -> 0 | AL8: =AK8/F8 -> 0 | AN8: =AM8/F8 -> 0 | AO8: 7 | AP8: =AO8/F8 -> 0.00012204265 | AQ8: 51 | AR8: =AQ8/F8 -> 0.00088916784 | AT8: =AS8/F8 -> 0 | AU8: 58 | AV8: =AU8/F8 -> 0.0010112105 | AW8: 36 | AX8: =AW8/F8 -> 0.00062764789
A9: ERIO CALCUTTA SPRINGS LTD. Howrah West Bengal | B9: Jan 2026 | C9: 07254988202255 DT. 14.06.2025 | D9: East Central | E9: ECR | F9: 64844 | G9: 64466 | H9: =G9/F9 -> 0.99417062 | I9: 378 | J9: =I9/F9 -> 0.0058293751 | K9: 4 | L9: =K9/F9 -> 6.1686509e-05 | M9: 50 | N9: =M9/F9 -> 0.00077108136 | O9: 42 | P9: =O9/F9 -> 0.00064770835 | R9: =Q9/F9 -> 0 | S9: 9 | T9: =S9/F9 -> 0.00013879465 | U9: 25 | V9: =U9/F9 -> 0.00038554068 | W9: 7 | X9: =W9/F9 -> 0.00010795139 | Z9: =Y9/F9 -> 0 | AB9: =AA9/F9 -> 0 | AC9: 26 | AD9: =AC9/F9 -> 0.00040096231 | AE9: 24 | AF9: =AE9/F9 -> 0.00037011905 | AH9: =AG9/F9 -> 0 | AJ9: =AI9/F9 -> 0 | AL9: =AK9/F9 -> 0 | AN9: =AM9/F9 -> 0 | AO9: 13 | AP9: =AO9/F9 -> 0.00020048115 | AQ9: 64 | AR9: =AQ9/F9 -> 0.00098698415 | AS9: 0 | AT9: =AS9/F9 -> 0 | AU9: 73 | AV9: =AU9/F9 -> 0.0011257788 | AX9: =AW9/F9 -> 0 | AY9: =SUM(K9:AX9) -> 337.0052 | AZ9: =AY9-I9 -> -40.994803
A10: ERIO CALCUTTA SPRINGS LTD. Howrah West Bengal | B10: Jan 2026 | C10: 61255131105052 Dt. 19.09.2025 | D10: North East Frontier | E10: NFR | F10: 237717 | G10: 235955 | H10: =G10/F10 -> 0.99258783 | I10: 1762 | J10: =I10/F10 -> 0.007412175 | K10: 160 | L10: =K10/F10 -> 0.00067306924 | M10: 204 | N10: =M10/F10 -> 0.00085816328 | O10: 126 | P10: =O10/F10 -> 0.00053004202 | R10: =Q10/F10 -> 0 | S10: 107 | T10: =S10/F10 -> 0.00045011505 | U10: 109 | V10: =U10/F10 -> 0.00045852842 | W10: 22 | X10: =W10/F10 -> 9.254702e-05 | Z10: =Y10/F10 -> 0 | AB10: =AA10/F10 -> 0 | AC10: 42 | AD10: =AC10/F10 -> 0.00017668067 | AE10: 55 | AF10: =AE10/F10 -> 0.00023136755 | AH10: =AG10/F10 -> 0 | AJ10: =AI10/F10 -> 0 | AL10: =AK10/F10 -> 0 | AN10: =AM10/F10 -> 0 | AO10: 31 | AP10: =AO10/F10 -> 0.00013040716 | AQ10: 407 | AR10: =AQ10/F10 -> 0.0017121199 | AS10: 41 | AT10: =AS10/F10 -> 0.00017247399 | AU10: 345 | AV10: =AU10/F10 -> 0.0014513055 | AX10: =AW10/F10 -> 0 | AY10: =SUM(K10:AX10) -> 1649.0069 | AZ10: =AY10-I10 -> -112.99306
A11: ERIO KALIMATA ISPAT (Unit-1) Howrah West Bengal | B11: December 2025 | C11: PO-60250003104659 DTD. 09.10.2025 | D11: South Eastern | E11: SER | F11: 195702 | G11: 192449 | H11: =G11/F11 -> 0.98337779 | I11: 3253 | J11: =I11/F11 -> 0.016622211 | K11: 145 | L11: =K11/F11 -> 0.00074092242 | M11: 728 | N11: =M11/F11 -> 0.0037199415 | O11: 77 | P11: =O11/F11 -> 0.00039345536 | Q11: 25 | R11: =Q11/F11 -> 0.00012774525 | S11: 51 | T11: =S11/F11 -> 0.0002606003 | U11: 755 | V11: =U11/F11 -> 0.0038579064 | W11: 0 | X11: =W11/F11 -> 0 | Z11: =Y11/F11 -> 0 | AB11: =AA11/F11 -> 0 | AD11: =AC11/F11 -> 0 | AE11: 0 | AF11: =AE11/F11 -> 0 | AH11: =AG11/F11 -> 0 | AJ11: =AI11/F11 -> 0 | AL11: =AK11/F11 -> 0 | AN11: =AM11/F11 -> 0 | AP11: =AO11/F11 -> 0 | AQ11: 722 | AR11: =AQ11/F11 -> 0.0036892827 | AT11: =AS11/F11 -> 0 | AU11: =285+405 -> 690 | AV11: =AU11/F11 -> 0.0035257688 | AW11: 60 | AX11: =AW11/F11 -> 0.00030658859
A12: ERIO KALIMATA ISPAT (Unit-1) Howrah West Bengal | B12: Jan 2026 | C12: 60250003104659 & DTD. 09.10.2025 | D12: South Eastern | E12: SER | F12: 112197 | G12: 110809 | H12: =G12/F12 -> 0.9876289 | I12: 1388 | J12: =I12/F12 -> 0.012371097 | K12: 33 | L12: =K12/F12 -> 0.00029412551 | M12: 80 | N12: =M12/F12 -> 0.00071303154 | O12: 46 | P12: =O12/F12 -> 0.00040999314 | Q12: 0 | R12: =Q12/F12 -> 0 | S12: 49 | T12: =S12/F12 -> 0.00043673182 | U12: 235 | V12: =U12/F12 -> 0.0020945302 | W12: 0 | X12: =W12/F12 -> 0 | Z12: =Y12/F12 -> 0 | AB12: =AA12/F12 -> 0 | AD12: =AC12/F12 -> 0 | AF12: =AE12/F12 -> 0 | AH12: =AG12/F12 -> 0 | AJ12: =AI12/F12 -> 0 | AL12: =AK12/F12 -> 0 | AN12: =AM12/F12 -> 0 | AP12: =AO12/F12 -> 0 | AQ12: 582 | AR12: =AQ12/F12 -> 0.0051873045 | AT12: =AS12/F12 -> 0 | AU12: 246 | AV12: =AU12/F12 -> 0.002192572 | AW12: 117 | AX12: =AW12/F12 -> 0.0010428086 | AY12: =SUM(K12:AX12) -> 1388.0124 | AZ12: =AY12-I12 -> 0.012371097
A13: ERIO KALIMATA ISPAT (Unit-1) Howrah West Bengal | B13: Jan 2026 | C13: 6325559204678 & DTD. 29.10.2025 | D13: North Western | E13: NWR | F13: 9979 | G13: 9920 | H13: =G13/F13 -> 0.99408758 | I13: 59 | J13: =I13/F13 -> 0.0059124161 | K13: 0 | L13: =K13/F13 -> 0 | M13: 6 | N13: =M13/F13 -> 0.00060126265 | O13: 0 | P13: =O13/F13 -> 0 | Q13: 0 | R13: =Q13/F13 -> 0 | S13: 0 | T13: =S13/F13 -> 0 | U13: 0 | V13: =U13/F13 -> 0 | W13: 0 | X13: =W13/F13 -> 0 | Z13: =Y13/F13 -> 0 | AB13: =AA13/F13 -> 0 | AD13: =AC13/F13 -> 0 | AF13: =AE13/F13 -> 0 | AH13: =AG13/F13 -> 0 | AJ13: =AI13/F13 -> 0 | AL13: =AK13/F13 -> 0 | AN13: =AM13/F13 -> 0 | AP13: =AO13/F13 -> 0 | AQ13: 42 | AR13: =AQ13/F13 -> 0.0042088386 | AT13: =AS13/F13 -> 0 | AU13: 0 | AV13: =AU13/F13 -> 0 | AW13: 11 | AX13: =AW13/F13 -> 0.0011023149 | AY13: =SUM(K13:AX13) -> 59.005912 | AZ13: =AY13-I13 -> 0.0059124161
A14: ERIO KALIMATA ISPAT (Unit-1) Howrah West Bengal | B14: Jan 2026 | C14: 60256836107122 & DTD. 08.12.2025 | D14: South Central | E14: SCR | F14: 155104 | G14: 153656 | H14: =G14/F14 -> 0.99066433 | I14: 1448 | J14: =I14/F14 -> 0.0093356715 | K14: 0 | L14: =K14/F14 -> 0 | M14: 265 | N14: =M14/F14 -> 0.0017085311 | O14: 175 | P14: =O14/F14 -> 0.0011282752 | Q14: 25 | R14: =Q14/F14 -> 0.00016118217 | S14: 47 | T14: =S14/F14 -> 0.00030302249 | U14: 207 | V14: =U14/F14 -> 0.0013345884 | W14: 10 | X14: =W14/F14 -> 6.447287e-05 | Z14: =Y14/F14 -> 0 | AB14: =AA14/F14 -> 0 | AD14: =AC14/F14 -> 0 | AF14: =AE14/F14 -> 0 | AH14: =AG14/F14 -> 0 | AJ14: =AI14/F14 -> 0 | AL14: =AK14/F14 -> 0 | AN14: =AM14/F14 -> 0 | AP14: =AO14/F14 -> 0 | AQ14: 358 | AR14: =AQ14/F14 -> 0.0023081287 | AT14: =AS14/F14 -> 0 | AU14: 7 | AV14: =AU14/F14 -> 4.5131009e-05 | AW14: 354 | AX14: =AW14/F14 -> 0.0022823396 | AY14: =SUM(K14:AX14) -> 1448.0093 | AZ14: =AY14-I14 -> 0.0093356715
A15: ERIO KALIMATA ISPAT (Unit-II) Durgapur West Bengal | B15: December 2025 | C15: 26245012101170 dated 16.05.2025 | D15: North Eastern | E15: NER | F15: 34416 | G15: 34011 | H15: =G15/F15 -> 0.98823222 | I15: 405 | J15: =I15/F15 -> 0.011767782 | L15: =K15/F15 -> 0 | M15: 0 | N15: =M15/F15 -> 0 | O15: 30 | P15: =O15/F15 -> 0.00087168759 | R15: =Q15/F15 -> 0 | S15: 138 | T15: =S15/F15 -> 0.0040097629 | U15: 198 | V15: =U15/F15 -> 0.0057531381 | X15: =W15/F15 -> 0 | Z15: =Y15/F15 -> 0 | AB15: =AA15/F15 -> 0 | AD15: =AC15/F15 -> 0 | AE15: 7 | AF15: =AE15/F15 -> 0.00020339377 | AH15: =AG15/F15 -> 0 | AJ15: =AI15/F15 -> 0 | AL15: =AK15/F15 -> 0 | AN15: =AM15/F15 -> 0 | AO15: 0 | AP15: =AO15/F15 -> 0 | AQ15: 31 | AR15: =AQ15/F15 -> 0.00090074384 | AT15: =AS15/F15 -> 0 | AV15: =AU15/F15 -> 0 | AW15: 1 | AX15: =AW15/F15 -> 2.9056253e-05
A16: ERIO KALIMATA ISPAT (Unit-II) Durgapur West Bengal | B16: December 2025 | C16: 61255204105004 dated 16.09.2025 | D16: North East Frontier | E16: NFR | F16: 17655 | G16: 17531 | H16: =G16/F16 -> 0.99297649 | I16: 124 | J16: =I16/F16 -> 0.0070235061 | L16: =K16/F16 -> 0 | M16: 0 | N16: =M16/F16 -> 0 | O16: 2 | P16: =O16/F16 -> 0.00011328236 | R16: =Q16/F16 -> 0 | S16: 53 | T16: =S16/F16 -> 0.0030019824 | U16: 52 | V16: =U16/F16 -> 0.0029453413 | X16: =W16/F16 -> 0 | Z16: =Y16/F16 -> 0 | AB16: =AA16/F16 -> 0 | AD16: =AC16/F16 -> 0 | AE16: 3 | AF16: =AE16/F16 -> 0.00016992353 | AH16: =AG16/F16 -> 0 | AJ16: =AI16/F16 -> 0 | AL16: =AK16/F16 -> 0 | AN16: =AM16/F16 -> 0 | AO16: 0 | AP16: =AO16/F16 -> 0 | AQ16: 14 | AR16: =AQ16/F16 -> 0.00079297649 | AT16: =AS16/F16 -> 0 | AV16: =AU16/F16 -> 0 | AW16: 0 | AX16: =AW16/F16 -> 0
A17: ERIO KALIMATA ISPAT (Unit-II) Durgapur West Bengal | B17: December 2025 | C17: 63255579204678 dated 29.10.2025 | D17: North Western | E17: NWR | F17: 109205 | G17: 108418 | H17: =G17/F17 -> 0.99279337 | I17: 787 | J17: =I17/F17 -> 0.0072066297 | L17: =K17/F17 -> 0 | M17: 12 | N17: =M17/F17 -> 0.00010988508 | O17: 89 | P17: =O17/F17 -> 0.000814981 | R17: =Q17/F17 -> 0 | S17: 296 | T17: =S17/F17 -> 0.0027104986 | U17: 337 | V17: =U17/F17 -> 0.0030859393 | X17: =W17/F17 -> 0 | Z17: =Y17/F17 -> 0 | AB17: =AA17/F17 -> 0 | AD17: =AC17/F17 -> 0 | AE17: 1 | AF17: =AE17/F17 -> 9.1570899e-06 | AH17: =AG17/F17 -> 0 | AJ17: =AI17/F17 -> 0 | AL17: =AK17/F17 -> 0 | AN17: =AM17/F17 -> 0 | AO17: 0 | AP17: =AO17/F17 -> 0 | AQ17: 52 | AR17: =AQ17/F17 -> 0.00047616867 | AT17: =AS17/F17 -> 0 | AV17: =AU17/F17 -> 0 | AW17: 0 | AX17: =AW17/F17 -> 0
A18: ERIO KALIMATA ISPAT (Unit-II) Durgapur West Bengal | B18: December 2025 | C18: 6255178103406 dated 03.11.2025 | D18: East Coast | E18: ECOR | F18: 262479 | G18: 260243 | H18: =G18/F18 -> 0.99148122 | I18: 2236 | J18: =I18/F18 -> 0.0085187767 | L18: =K18/F18 -> 0 | M18: 32 | N18: =M18/F18 -> 0.00012191452 | O18: 279 | P18: =O18/F18 -> 0.0010629422 | R18: =Q18/F18 -> 0 | S18: 933 | T18: =S18/F18 -> 0.0035545701 | U18: 788 | V18: =U18/F18 -> 0.0030021449 | X18: =W18/F18 -> 0 | Z18: =Y18/F18 -> 0 | AB18: =AA18/F18 -> 0 | AD18: =AC18/F18 -> 0 | AE18: 11 | AF18: =AE18/F18 -> 4.1908115e-05 | AH18: =AG18/F18 -> 0 | AJ18: =AI18/F18 -> 0 | AL18: =AK18/F18 -> 0 | AN18: =AM18/F18 -> 0 | AO18: 3 | AP18: =AO18/F18 -> 1.1429486e-05 | AQ18: 161 | AR18: =AQ18/F18 -> 0.0006133824 | AT18: =AS18/F18 -> 0 | AV18: =AU18/F18 -> 0 | AW18: 29 | AX18: =AW18/F18 -> 0.00011048503
A19: ERIO KALIMATA ISPAT (Unit-II) Durgapur West Bengal | B19: Jan 2026 | C19: 26245012101170 & 16.05.2025 | D19: North Eastern | E19: NER | F19: 121363 | G19: 120592 | H19: =G19/F19 -> 0.99364716 | I19: 771 | J19: =I19/F19 -> 0.0063528423 | K19: 0 | L19: =K19/F19 -> 0 | M19: 28 | N19: =M19/F19 -> 0.00023071282 | O19: 94 | P19: =O19/F19 -> 0.0007745359 | R19: =Q19/F19 -> 0 | S19: 229 | T19: =S19/F19 -> 0.0018869013 | U19: 345 | V19: =U19/F19 -> 0.0028427115 | X19: =W19/F19 -> 0 | Z19: =Y19/F19 -> 0 | AB19: =AA19/F19 -> 0 | AC19: 0 | AD19: =AC19/F19 -> 0 | AE19: 0 | AF19: =AE19/F19 -> 0 | AH19: =AG19/F19 -> 0 | AJ19: =AI19/F19 -> 0 | AL19: =AK19/F19 -> 0 | AN19: =AM19/F19 -> 0 | AO19: 14 | AP19: =AO19/F19 -> 0.00011535641 | AQ19: 60 | AR19: =AQ19/F19 -> 0.00049438461 | AT19: =AS19/F19 -> 0 | AU19: 0 | AV19: =AU19/F19 -> 0 | AW19: 1 | AX19: =AW19/F19 -> 8.2397436e-06 | AY19: =SUM(K19:AX19) -> 771.00635 | AZ19: =AY19-I19 -> 0.0063528423
A20: ERIO KALIMATA ISPAT (Unit-II) Durgapur West Bengal | B20: Jan 2026 | C20: 63255579204678 & 29.10.2025 | D20: North Western | E20: NWR | F20: 79919 | G20: 79448 | H20: =G20/F20 -> 0.99410653 | I20: 471 | J20: =I20/F20 -> 0.0058934671 | K20: 1 | L20: =K20/F20 -> 1.2512669e-05 | M20: 15 | N20: =M20/F20 -> 0.00018769004 | O20: 55 | P20: =O20/F20 -> 0.0006881968 | R20: =Q20/F20 -> 0 | S20: 146 | T20: =S20/F20 -> 0.0018268497 | U20: 146 | V20: =U20/F20 -> 0.0018268497 | X20: =W20/F20 -> 0 | Z20: =Y20/F20 -> 0 | AB20: =AA20/F20 -> 0 | AC20: 1 | AD20: =AC20/F20 -> 1.2512669e-05 | AE20: 0 | AF20: =AE20/F20 -> 0 | AH20: =AG20/F20 -> 0 | AJ20: =AI20/F20 -> 0 | AL20: =AK20/F20 -> 0 | AN20: =AM20/F20 -> 0 | AO20: 8 | AP20: =AO20/F20 -> 0.00010010135 | AQ20: 99 | AR20: =AQ20/F20 -> 0.0012387542 | AT20: =AS20/F20 -> 0 | AU20: 0 | AV20: =AU20/F20 -> 0 | AW20: 0 | AX20: =AW20/F20 -> 0 | AY20: =SUM(K20:AX20) -> 471.00589 | AZ20: =AY20-I20 -> 0.0058934671
A21: ERIO KALIMATA ISPAT (Unit-II) Durgapur West Bengal | B21: Jan 2026 | C21: 03255541205744 & 22.11.2025 | D21: Southern | E21: SR | F21: 186716 | G21: 185510 | H21: =G21/F21 -> 0.99354099 | I21: 1206 | J21: =I21/F21 -> 0.0064590073 | K21: 0 | L21: =K21/F21 -> 0 | M21: 42 | N21: =M21/F21 -> 0.00022494055 | O21: 168 | P21: =O21/F21 -> 0.00089976221 | R21: =Q21/F21 -> 0 | S21: 323 | T21: =S21/F21 -> 0.0017299 | U21: 498 | V21: =U21/F21 -> 0.0026671523 | X21: =W21/F21 -> 0 | Z21: =Y21/F21 -> 0 | AB21: =AA21/F21 -> 0 | AC21: 0 | AD21: =AC21/F21 -> 0 | AE21: 0 | AF21: =AE21/F21 -> 0 | AH21: =AG21/F21 -> 0 | AJ21: =AI21/F21 -> 0 | AL21: =AK21/F21 -> 0 | AN21: =AM21/F21 -> 0 | AO21: 7 | AP21: =AO21/F21 -> 3.7490092e-05 | AQ21: 150 | AR21: =AQ21/F21 -> 0.00080335911 | AT21: =AS21/F21 -> 0 | AU21: 12 | AV21: =AU21/F21 -> 6.4268729e-05 | AW21: 6 | AX21: =AW21/F21 -> 3.2134364e-05 | AY21: =SUM(K21:AX21) -> 1206.0065 | AZ21: =AY21-I21 -> 0.0064590073
A22: ERIO KALIMATA ISPAT (Unit-II) Durgapur West Bengal | B22: Jan 2026 | C22: 60256836107122 & 08.12.2025 | D22: South Central | E22: SCR | F22: 65523 | G22: 65211 | H22: =G22/F22 -> 0.99523831 | I22: 312 | J22: =I22/F22 -> 0.0047616867 | K22: 2 | L22: =K22/F22 -> 3.0523633e-05 | M22: 97 | N22: =M22/F22 -> 0.0014803962 | O22: 69 | P22: =O22/F22 -> 0.0010530653 | R22: =Q22/F22 -> 0 | S22: 0 | T22: =S22/F22 -> 0 | U22: 0 | V22: =U22/F22 -> 0 | X22: =W22/F22 -> 0 | Z22: =Y22/F22 -> 0 | AB22: =AA22/F22 -> 0 | AC22: 0 | AD22: =AC22/F22 -> 0 | AE22: 2 | AF22: =AE22/F22 -> 3.0523633e-05 | AH22: =AG22/F22 -> 0 | AJ22: =AI22/F22 -> 0 | AL22: =AK22/F22 -> 0 | AN22: =AM22/F22 -> 0 | AO22: 14 | AP22: =AO22/F22 -> 0.00021366543 | AQ22: 111 | AR22: =AQ22/F22 -> 0.0016940616 | AT22: =AS22/F22 -> 0 | AU22: 2 | AV22: =AU22/F22 -> 3.0523633e-05 | AW22: 15 | AX22: =AW22/F22 -> 0.00022892725 | AY22: =SUM(K22:AX22) -> 312.00476 | AZ22: =AY22-I22 -> 0.0047616867
A23: ERIO KALIMATA VYAPAAR (Unit-II) Durgapur West Bengal | B23: December 2025 | C23: 60257500205477 dated 10.09.2025 | D23: South Central | E23: SCR | F23: 43707 | G23: 43179 | H23: =G23/F23 -> 0.98791956 | I23: 528 | J23: =I23/F23 -> 0.012080445 | L23: =K23/F23 -> 0 | M23: 6 | N23: =M23/F23 -> 0.00013727778 | O23: 124 | P23: =O23/F23 -> 0.0028370742 | R23: =Q23/F23 -> 0 | S23: 150 | T23: =S23/F23 -> 0.0034319445 | U23: 166 | V23: =U23/F23 -> 0.0037980186 | X23: =W23/F23 -> 0 | Z23: =Y23/F23 -> 0 | AB23: =AA23/F23 -> 0 | AD23: =AC23/F23 -> 0 | AE23: 0 | AF23: =AE23/F23 -> 0 | AH23: =AG23/F23 -> 0 | AJ23: =AI23/F23 -> 0 | AL23: =AK23/F23 -> 0 | AN23: =AM23/F23 -> 0 | AP23: =AO23/F23 -> 0 | AQ23: 82 | AR23: =AQ23/F23 -> 0.0018761297 | AS23: 0 | AT23: =AS23/F23 -> 0 | AV23: =AU23/F23 -> 0 | AW23: 0 | AX23: =AW23/F23 -> 0
A24: ERIO KALIMATA VYAPAAR (Unit-II) Durgapur West Bengal | B24: December 2025 | C24: 03255362204668 dated 12.09.2025 | D24: Southern | E24: SR | F24: 178635 | G24: 176175 | H24: =G24/F24 -> 0.9862289 | I24: 2460 | J24: =I24/F24 -> 0.013771097 | L24: =K24/F24 -> 0 | M24: 1 | N24: =M24/F24 -> 5.5980071e-06 | O24: 159 | P24: =O24/F24 -> 0.00089008313 | R24: =Q24/F24 -> 0 | S24: 927 | T24: =S24/F24 -> 0.0051893526 | U24: 832 | V24: =U24/F24 -> 0.0046575419 | X24: =W24/F24 -> 0 | Z24: =Y24/F24 -> 0 | AB24: =AA24/F24 -> 0 | AD24: =AC24/F24 -> 0 | AE24: 21 | AF24: =AE24/F24 -> 0.00011755815 | AH24: =AG24/F24 -> 0 | AJ24: =AI24/F24 -> 0 | AL24: =AK24/F24 -> 0 | AN24: =AM24/F24 -> 0 | AP24: =AO24/F24 -> 0 | AQ24: 516 | AR24: =AQ24/F24 -> 0.0028885717 | AS24: 0 | AT24: =AS24/F24 -> 0 | AV24: =AU24/F24 -> 0 | AW24: 4 | AX24: =AW24/F24 -> 2.2392028e-05
A25: ERIO KALIMATA VYAPAAR (Unit-II) Durgapur West Bengal | B25: December 2025 | C25: 60250003104658 dated 09.10.2025 | D25: South Eastern | E25: SER | F25: 195626 | G25: 192833 | H25: =G25/F25 -> 0.98572276 | I25: 2793 | J25: =I25/F25 -> 0.014277243 | L25: =K25/F25 -> 0 | M25: 203 | N25: =M25/F25 -> 0.0010376944 | O25: 394 | P25: =O25/F25 -> 0.0020140472 | R25: =Q25/F25 -> 0 | S25: 883 | T25: =S25/F25 -> 0.0045137149 | U25: 812 | V25: =U25/F25 -> 0.0041507775 | X25: =W25/F25 -> 0 | Z25: =Y25/F25 -> 0 | AB25: =AA25/F25 -> 0 | AD25: =AC25/F25 -> 0 | AE25: 23 | AF25: =AE25/F25 -> 0.00011757128 | AH25: =AG25/F25 -> 0 | AJ25: =AI25/F25 -> 0 | AL25: =AK25/F25 -> 0 | AN25: =AM25/F25 -> 0 | AP25: =AO25/F25 -> 0 | AQ25: 474 | AR25: =AQ25/F25 -> 0.0024229908 | AS25: 0 | AT25: =AS25/F25 -> 0 | AV25: =AU25/F25 -> 0 | AW25: 4 | AX25: =AW25/F25 -> 2.044718e-05
A26: ERIO KALIMATA VYAPAAR (Unit-II) Durgapur West Bengal | B26: December 2025 | C26: 63255579204677 dated 29.10.2025 | D26: North Western | E26: NWR | F26: 16555 | G26: 16299 | H26: =G26/F26 -> 0.98453639 | I26: 256 | J26: =I26/F26 -> 0.015463606 | L26: =K26/F26 -> 0 | M26: 0 | N26: =M26/F26 -> 0 | O26: 70 | P26: =O26/F26 -> 0.0042283298 | R26: =Q26/F26 -> 0 | S26: 70 | T26: =S26/F26 -> 0.0042283298 | U26: 67 | V26: =U26/F26 -> 0.0040471157 | X26: =W26/F26 -> 0 | Z26: =Y26/F26 -> 0 | AB26: =AA26/F26 -> 0 | AD26: =AC26/F26 -> 0 | AE26: 0 | AF26: =AE26/F26 -> 0 | AH26: =AG26/F26 -> 0 | AJ26: =AI26/F26 -> 0 | AL26: =AK26/F26 -> 0 | AN26: =AM26/F26 -> 0 | AP26: =AO26/F26 -> 0 | AQ26: 48 | AR26: =AQ26/F26 -> 0.0028994262 | AS26: 0 | AT26: =AS26/F26 -> 0 | AV26: =AU26/F26 -> 0 | AW26: 1 | AX26: =AW26/F26 -> 6.0404712e-05
A27: ERIO KALIMATA VYAPAAR (Unit-II) Durgapur West Bengal | B27: December 2025 | C27: 06255399103608 dated 21.11.2025 | D27: East Coast | E27: ECOR | F27: 67325 | G27: 66662 | H27: =G27/F27 -> 0.99015225 | I27: 663 | J27: =I27/F27 -> 0.0098477534 | L27: =K27/F27 -> 0 | M27: 134 | N27: =M27/F27 -> 0.0019903453 | O27: 186 | P27: =O27/F27 -> 0.0027627182 | R27: =Q27/F27 -> 0 | S27: 0 | T27: =S27/F27 -> 0 | U27: 0 | V27: =U27/F27 -> 0 | X27: =W27/F27 -> 0 | Z27: =Y27/F27 -> 0 | AB27: =AA27/F27 -> 0 | AD27: =AC27/F27 -> 0 | AE27: 5 | AF27: =AE27/F27 -> 7.4266617e-05 | AH27: =AG27/F27 -> 0 | AJ27: =AI27/F27 -> 0 | AL27: =AK27/F27 -> 0 | AN27: =AM27/F27 -> 0 | AP27: =AO27/F27 -> 0 | AQ27: 227 | AR27: =AQ27/F27 -> 0.0033717044 | AS27: 55 | AT27: =AS27/F27 -> 0.00081693279 | AV27: =AU27/F27 -> 0 | AW27: 56 | AX27: =AW27/F27 -> 0.00083178611
A28: ERIO KALIMATA VYAPAAR (Unit-II) Durgapur West Bengal | B28: Jan 2026 | C28: 63255579204677 & 29.10.2025 | D28: North Western | E28: NWR | F28: 404458 | G28: 397681 | H28: =G28/F28 -> 0.98324424 | I28: 6777 | J28: =I28/F28 -> 0.016755757 | L28: =K28/F28 -> 0 | M28: 107 | N28: =M28/F28 -> 0.00026455157 | O28: 1599 | P28: =O28/F28 -> 0.0039534389 | R28: =Q28/F28 -> 0 | S28: 1581 | T28: =S28/F28 -> 0.0039089349 | U28: 1638 | V28: =U28/F28 -> 0.0040498643 | X28: =W28/F28 -> 0 | Z28: =Y28/F28 -> 0 | AB28: =AA28/F28 -> 0 | AD28: =AC28/F28 -> 0 | AE28: 12 | AF28: =AE28/F28 -> 2.9669335e-05 | AH28: =AG28/F28 -> 0 | AJ28: =AI28/F28 -> 0 | AL28: =AK28/F28 -> 0 | AN28: =AM28/F28 -> 0 | AP28: =AO28/F28 -> 0 | AQ28: 1069 | AR28: =AQ28/F28 -> 0.0026430433 | AT28: =AS28/F28 -> 0 | AV28: =AU28/F28 -> 0 | AW28: 771 | AX28: =AW28/F28 -> 0.0019062548 | AY28: =SUM(K28:AX28) -> 6777.0168 | AZ28: =AY28-I28 -> 0.016755757
A29: ERIO KALIMATA VYAPAAR (Unit-II) Durgapur West Bengal | B29: Jan 2026 | C29: 06255399103608 & 21.11.2025 | D29: East Coast | E29: ECOR | F29: 284 | G29: 264 | H29: =G29/F29 -> 0.92957746 | I29: 20 | J29: =I29/F29 -> 0.070422535 | L29: =K29/F29 -> 0 | M29: 0 | N29: =M29/F29 -> 0 | O29: 14 | P29: =O29/F29 -> 0.049295775 | R29: =Q29/F29 -> 0 | S29: 0 | T29: =S29/F29 -> 0 | U29: 0 | V29: =U29/F29 -> 0 | X29: =W29/F29 -> 0 | Z29: =Y29/F29 -> 0 | AB29: =AA29/F29 -> 0 | AD29: =AC29/F29 -> 0 | AE29: 0 | AF29: =AE29/F29 -> 0 | AH29: =AG29/F29 -> 0 | AJ29: =AI29/F29 -> 0 | AL29: =AK29/F29 -> 0 | AN29: =AM29/F29 -> 0 | AP29: =AO29/F29 -> 0 | AQ29: 6 | AR29: =AQ29/F29 -> 0.021126761 | AT29: =AS29/F29 -> 0 | AV29: =AU29/F29 -> 0 | AW29: 0 | AX29: =AW29/F29 -> 0 | AY29: =SUM(K29:AX29) -> 20.070423 | AZ29: =AY29-I29 -> 0.070422535
A30: ERIO KALIMATA VYAPAAR (Unit-II) Durgapur West Bengal | B30: Jan 2026 | C30: 03255541205771 & 24.11.2025 | D30: Southern | E30: SR | F30: 121602 | G30: 119728 | H30: =G30/F30 -> 0.98458907 | I30: 1874 | J30: =I30/F30 -> 0.015410931 | L30: =K30/F30 -> 0 | M30: 5 | N30: =M30/F30 -> 4.1117745e-05 | O30: 488 | P30: =O30/F30 -> 0.0040130919 | R30: =Q30/F30 -> 0 | S30: 514 | T30: =S30/F30 -> 0.0042269042 | U30: 564 | V30: =U30/F30 -> 0.0046380816 | X30: =W30/F30 -> 0 | Z30: =Y30/F30 -> 0 | AB30: =AA30/F30 -> 0 | AD30: =AC30/F30 -> 0 | AE30: 0 | AF30: =AE30/F30 -> 0 | AH30: =AG30/F30 -> 0 | AJ30: =AI30/F30 -> 0 | AL30: =AK30/F30 -> 0 | AN30: =AM30/F30 -> 0 | AP30: =AO30/F30 -> 0 | AQ30: 287 | AR30: =AQ30/F30 -> 0.0023601586 | AT30: =AS30/F30 -> 0 | AV30: =AU30/F30 -> 0 | AW30: 16 | AX30: =AW30/F30 -> 0.00013157678 | AY30: =SUM(K30:AX30) -> 1874.0154 | AZ30: =AY30-I30 -> 0.015410931
A31: ERIO KDS ENGG. PVT. LTD. Howrah West Bengal | B31: December 2025 | C31: NO PRODUCTION | F31: 0 | G31: 0 | H31: =G31/F31 -> #DIV/0! | I31: 0 | J31: =I31/F31 -> #DIV/0! | L31: =K31/F31 -> #DIV/0! | N31: =M31/F31 -> #DIV/0! | P31: =O31/F31 -> #DIV/0! | R31: =Q31/F31 -> #DIV/0! | T31: =S31/F31 -> #DIV/0! | V31: =U31/F31 -> #DIV/0! | X31: =W31/F31 -> #DIV/0! | Z31: =Y31/F31 -> #DIV/0! | AB31: =AA31/F31 -> #DIV/0! | AD31: =AC31/F31 -> #DIV/0! | AF31: =AE31/F31 -> #DIV/0! | AH31: =AG31/F31 -> #DIV/0! | AJ31: =AI31/F31 -> #DIV/0! | AL31: =AK31/F31 -> #DIV/0! | AN31: =AM31/F31 -> #DIV/0! | AP31: =AO31/F31 -> #DIV/0! | AR31: =AQ31/F31 -> #DIV/0! | AT31: =AS31/F31 -> #DIV/0! | AV31: =AU31/F31 -> #DIV/0! | AX31: =AW31/F31 -> #DIV/0!
A32: ERIO KDS ENGG. PVT. LTD. Howrah West Bengal | B32: Jan 2026 | C32: 26255279200322 DT-13.01.2026 | D32: Western | E32: WR | F32: 39589 | G32: 39266 | H32: =G32/F32 -> 0.99184117 | I32: 323 | J32: =I32/F32 -> 0.008158832 | L32: =K32/F32 -> 0 | M32: 125 | N32: =M32/F32 -> 0.0031574427 | P32: =O32/F32 -> 0 | R32: =Q32/F32 -> 0 | S32: 41 | T32: =S32/F32 -> 0.0010356412 | U32: 71 | V32: =U32/F32 -> 0.0017934275 | W32: 10 | X32: =W32/F32 -> 0.00025259542 | Z32: =Y32/F32 -> 0 | AB32: =AA32/F32 -> 0 | AC32: 4 | AD32: =AC32/F32 -> 0.00010103817 | AF32: =AE32/F32 -> 0 | AH32: =AG32/F32 -> 0 | AJ32: =AI32/F32 -> 0 | AL32: =AK32/F32 -> 0 | AN32: =AM32/F32 -> 0 | AP32: =AO32/F32 -> 0 | AQ32: 46 | AR32: =AQ32/F32 -> 0.0011619389 | AS32: 20 | AT32: =AS32/F32 -> 0.00050519084 | AU32: 6 | AV32: =AU32/F32 -> 0.00015155725 | AX32: =AW32/F32 -> 0 | AY32: =SUM(K32:AX32) -> 323.00816 | AZ32: =AY32-I32 -> 0.008158832
A33: ERIO KRISHNA INFRATECH Jharsuguda Odisha | B33: December 2025 | C33: 77255086207682 DT 15.10.2025 | D33: Northern | E33: NR | F33: =G33+I33 -> 50926 | G33: 50410 | H33: =G33/F33 -> 0.98986765 | I33: 516 | J33: =I33/F33 -> 0.010132349 | L33: =K33/F33 -> 0 | M33: 246 | N33: =M33/F33 -> 0.0048305384 | O33: 103 | P33: =O33/F33 -> 0.0020225425 | R33: =Q33/F33 -> 0 | T33: =S33/F33 -> 0 | U33: 105 | V33: =U33/F33 -> 0.0020618152 | X33: =W33/F33 -> 0 | Z33: =Y33/F33 -> 0 | AB33: =AA33/F33 -> 0 | AD33: =AC33/F33 -> 0 | AF33: =AE33/F33 -> 0 | AH33: =AG33/F33 -> 0 | AJ33: =AI33/F33 -> 0 | AL33: =AK33/F33 -> 0 | AN33: =AM33/F33 -> 0 | AO33: 12 | AP33: =AO33/F33 -> 0.00023563602 | AQ33: 50 | AR33: =AQ33/F33 -> 0.00098181675 | AT33: =AS33/F33 -> 0 | AV33: =AU33/F33 -> 0 | AX33: =AW33/F33 -> 0
A34: ERIO KRISHNA INFRATECH Jharsuguda Odisha | B34: December 2025 | C34: 77255086207682 DT 15.10.2026 | D34: Northern | E34: NR | F34: =G34+I34 -> 8267 | G34: 8190 | H34: =G34/F34 -> 0.99068586 | I34: 77 | J34: =I34/F34 -> 0.0093141406 | L34: =K34/F34 -> 0 | M34: 43 | N34: =M34/F34 -> 0.0052014032 | O34: 22 | P34: =O34/F34 -> 0.002661183 | R34: =Q34/F34 -> 0 | T34: =S34/F34 -> 0 | U34: 0 | V34: =U34/F34 -> 0 | X34: =W34/F34 -> 0 | Z34: =Y34/F34 -> 0 | AB34: =AA34/F34 -> 0 | AD34: =AC34/F34 -> 0 | AF34: =AE34/F34 -> 0 | AH34: =AG34/F34 -> 0 | AJ34: =AI34/F34 -> 0 | AL34: =AK34/F34 -> 0 | AN34: =AM34/F34 -> 0 | AO34: 5 | AP34: =AO34/F34 -> 0.00060481432 | AQ34: 7 | AR34: =AQ34/F34 -> 0.00084674005 | AT34: =AS34/F34 -> 0 | AV34: =AU34/F34 -> 0 | AX34: =AW34/F34 -> 0
A35: ERIO KRISHNA INFRATECH Jharsuguda Odisha | B35: December 2025 | C35: 06255178103407 DT 03.11.2025 | D35: East Coast | E35: ECoR | F35: =G35+I35 -> 169531 | G35: 167810 | H35: =G35/F35 -> 0.98984846 | I35: 1721 | J35: =I35/F35 -> 0.010151536 | L35: =K35/F35 -> 0 | M35: 792 | N35: =M35/F35 -> 0.004671712 | O35: 341 | P35: =O35/F35 -> 0.0020114315 | R35: =Q35/F35 -> 0 | T35: =S35/F35 -> 0 | U35: 326 | V35: =U35/F35 -> 0.0019229521 | X35: =W35/F35 -> 0 | Z35: =Y35/F35 -> 0 | AB35: =AA35/F35 -> 0 | AD35: =AC35/F35 -> 0 | AF35: =AE35/F35 -> 0 | AH35: =AG35/F35 -> 0 | AJ35: =AI35/F35 -> 0 | AL35: =AK35/F35 -> 0 | AN35: =AM35/F35 -> 0 | AO35: 41 | AP35: =AO35/F35 -> 0.00024184367 | AQ35: 179 | AR35: =AQ35/F35 -> 0.0010558541 | AT35: =AS35/F35 -> 0 | AV35: =AU35/F35 -> 0 | AX35: =AW35/F35 -> 0
A36: ERIO KRISHNA INFRATECH Jharsuguda Odisha | B36: Jan 2026 | C36: 06255178103407 DT 03.11.2025 | D36: East Coast | E36: ECoR | F36: 131959 | G36: 130800 | H36: =G36/F36 -> 0.99121697 | I36: 1159 | J36: =I36/F36 -> 0.0087830311 | L36: =K36/F36 -> 0 | M36: 452 | N36: =M36/F36 -> 0.0034253063 | O36: 389 | P36: =O36/F36 -> 0.0029478853 | R36: =Q36/F36 -> 0 | T36: =S36/F36 -> 0 | U36: 146 | V36: =U36/F36 -> 0.0011064043 | X36: =W36/F36 -> 0 | Z36: =Y36/F36 -> 0 | AB36: =AA36/F36 -> 0 | AD36: =AC36/F36 -> 0 | AF36: =AE36/F36 -> 0 | AH36: =AG36/F36 -> 0 | AJ36: =AI36/F36 -> 0 | AL36: =AK36/F36 -> 0 | AN36: =AM36/F36 -> 0 | AO36: 21 | AP36: =AO36/F36 -> 0.00015914034 | AQ36: 151 | AR36: =AQ36/F36 -> 0.0011442948 | AT36: =AS36/F36 -> 0 | AV36: =AU36/F36 -> 0 | AX36: =AW36/F36 -> 0 | AY36: =SUM(K36:AX36) -> 1159.0088 | AZ36: =AY36-I36 -> 0.0087830311
A37: ERIO KSE ELECTRICALS PVT LTD Howrah West Bengal | B37: December 2025 | C37: 77235519205935 DT 29- JULY-2024 | D37: Northern | E37: NR | F37: =G37+I37 -> 118730 | G37: 117600 | H37: =G37/F37 -> 0.99048261 | I37: 1130 | J37: =I37/F37 -> 0.0095173924 | K37: 78 | L37: =K37/F37 -> 0.00065695275 | M37: 118 | N37: =M37/F37 -> 0.0009938516 | O37: 0 | P37: =O37/F37 -> 0 | R37: =Q37/F37 -> 0 | S37: 167 | T37: =S37/F37 -> 0.0014065527 | U37: 287 | V37: =U37/F37 -> 0.0024172492 | W37: 40 | X37: =W37/F37 -> 0.00033689885 | Z37: =Y37/F37 -> 0 | AB37: =AA37/F37 -> 0 | AC37: 68 | AD37: =AC37/F37 -> 0.00057272804 | AF37: =AE37/F37 -> 0 | AH37: =AG37/F37 -> 0 | AJ37: =AI37/F37 -> 0 | AL37: =AK37/F37 -> 0 | AN37: =AM37/F37 -> 0 | AO37: 3 | AP37: =AO37/F37 -> 2.5267413e-05 | AQ37: 116 | AR37: =AQ37/F37 -> 0.00097700665 | AS37: 110 | AT37: =AS37/F37 -> 0.00092647183 | AU37: 143 | AV37: =AU37/F37 -> 0.0012044134 | AX37: =AW37/F37 -> 0
A38: ERIO KSE ELECTRICALS PVT LTD Howrah West Bengal | B38: December 2025 | C38: 63255372202186 DT 10- JUN-2025 | D38: North Western | E38: NWR | F38: =G38+I38 -> 110579 | G38: 109480 | H38: =G38/F38 -> 0.9900614 | I38: 1099 | J38: =I38/F38 -> 0.0099385959 | K38: 39 | L38: =K38/F38 -> 0.00035268903 | M38: 157 | N38: =M38/F38 -> 0.0014197994 | O38: 0 | P38: =O38/F38 -> 0 | R38: =Q38/F38 -> 0 | S38: 144 | T38: =S38/F38 -> 0.0013022364 | U38: 334 | V38: =U38/F38 -> 0.003020465 | W38: 62 | X38: =W38/F38 -> 0.00056068512 | Z38: =Y38/F38 -> 0 | AB38: =AA38/F38 -> 0 | AC38: 83 | AD38: =AC38/F38 -> 0.0007505946 | AF38: =AE38/F38 -> 0 | AH38: =AG38/F38 -> 0 | AJ38: =AI38/F38 -> 0 | AL38: =AK38/F38 -> 0 | AN38: =AM38/F38 -> 0 | AO38: 0 | AP38: =AO38/F38 -> 0 | AQ38: 98 | AR38: =AQ38/F38 -> 0.00088624422 | AS38: 31 | AT38: =AS38/F38 -> 0.00028034256 | AU38: 151 | AV38: =AU38/F38 -> 0.0013655396 | AX38: =AW38/F38 -> 0
A39: ERIO KSE ELECTRICALS PVT LTD Howrah West Bengal | B39: December 2025 | C39: 01245150200865 DT 27- JUN-2025 | D39: North East Frontier | E39: NFR | F39: =G39+I39 -> 206706 | G39: 204700 | H39: =G39/F39 -> 0.9902954 | I39: 2006 | J39: =I39/F39 -> 0.0097046046 | K39: 169 | L39: =K39/F39 -> 0.00081758633 | M39: 200 | N39: =M39/F39 -> 0.00096755779 | O39: 0 | P39: =O39/F39 -> 0 | R39: =Q39/F39 -> 0 | S39: 205 | T39: =S39/F39 -> 0.00099174673 | U39: 505 | V39: =U39/F39 -> 0.0024430834 | W39: 197 | X39: =W39/F39 -> 0.00095304442 | Z39: =Y39/F39 -> 0 | AB39: =AA39/F39 -> 0 | AC39: 148 | AD39: =AC39/F39 -> 0.00071599276 | AF39: =AE39/F39 -> 0 | AH39: =AG39/F39 -> 0 | AJ39: =AI39/F39 -> 0 | AL39: =AK39/F39 -> 0 | AN39: =AM39/F39 -> 0 | AO39: 0 | AP39: =AO39/F39 -> 0 | AQ39: 168 | AR39: =AQ39/F39 -> 0.00081274854 | AS39: 144 | AT39: =AS39/F39 -> 0.00069664161 | AU39: 270 | AV39: =AU39/F39 -> 0.001306203 | AX39: =AW39/F39 -> 0
A40: ERIO KSE ELECTRICALS PVT LTD Howrah West Bengal | B40: December 2025 | C40: 81255001102836 DT 21- JULY-2025 | D40: West Central | E40: WCR | F40: =G40+I40 -> 115270 | G40: 114400 | H40: =G40/F40 -> 0.9924525 | I40: 870 | J40: =I40/F40 -> 0.0075474972 | K40: 39 | L40: =K40/F40 -> 0.00033833608 | M40: 133 | N40: =M40/F40 -> 0.0011538128 | O40: 0 | P40: =O40/F40 -> 0 | R40: =Q40/F40 -> 0 | S40: 114 | T40: =S40/F40 -> 0.00098898239 | U40: 260 | V40: =U40/F40 -> 0.0022555739 | W40: 14 | X40: =W40/F40 -> 0.00012145398 | Z40: =Y40/F40 -> 0 | AB40: =AA40/F40 -> 0 | AC40: 36 | AD40: =AC40/F40 -> 0.00031231023 | AF40: =AE40/F40 -> 0 | AH40: =AG40/F40 -> 0 | AJ40: =AI40/F40 -> 0 | AL40: =AK40/F40 -> 0 | AN40: =AM40/F40 -> 0 | AO40: 0 | AP40: =AO40/F40 -> 0 | AQ40: 115 | AR40: =AQ40/F40 -> 0.00099765767 | AS40: 28 | AT40: =AS40/F40 -> 0.00024290796 | AU40: 131 | AV40: =AU40/F40 -> 0.0011364622 | AX40: =AW40/F40 -> 0
...

Sheet Copy of Final Month Wise Defect
A2: Firm Name | B2: Month | C2: Inspected (Nos.) | D2: Acceptance (Nos.) | E2: % Acceptance | F2: Rejection (Nos.) | G2: % Rejection | H2: Visual (Sheared Edges, Surface Defects) | I2: ="%"&H2 -> %Visual (Sheared Edges, Surface Defects) | J2: Dimensional | K2: ="%"&J2 -> %Dimensional | L2: Cut bar length | M2: ="%"&L2 -> %Cut bar length | N2: Cut Bar diameter | O2: ="%"&N2 -> %Cut Bar diameter | P2: Turning length | Q2: ="%"&P2 -> %Turning length | R2: Turning Bar Diameter | S2: ="%"&R2 -> %Turning Bar Diameter | T2: Flat Bearing Area | U2: ="%"&T2 -> %Flat Bearing Area | V2: Application & Deflection test | W2: ="%"&V2 -> %Application & Deflection test | X2: Chemical Composition | Y2: ="%"&X2 -> %Chemical Composition | Z2: Toe load | AA2: ="%"&Z2 -> %Toe load | AB2: Hardness | AC2: ="%"&AB2 -> %Hardness | AD2: Microstructure | AE2: ="%"&AD2 -> %Microstructure | AF2: Grain size | AG2: ="%"&AF2 -> %Grain size | AH2: Depth of Decarburization | AI2: ="%"&AH2 -> %Depth of Decarburization | AJ2: Inclusion rating | AK2: ="%"&AJ2 -> %Inclusion rating | AL2: MPI | AM2: ="%"&AL2 -> %MPI | AN2: Forging defect | AO2: ="%"&AN2 -> %Forging defect | AP2: Marking | AQ2: ="%"&AP2 -> %Marking | AR2: Embossing Die Impression / Failure | AS2: ="%"&AR2 -> %Embossing Die Impression / Failure | AT2: Other (less weight) | AU2: ="%"&AT2 -> %Other (less weight)
A3: ERIO AMBE FASTNERS PVT.LTD. Patna Bihar | B3: May 2025 | C3: =D3+F3 -> 34664 | D3: 34447 | E3: =D3/C3 -> 0.9937399 | F3: 217 | G3: =F3/$C3 -> 0.0062600969 | H3: 5 | I3: =H3/$C3 -> 0.00014424186 | J3: 26 | K3: =J3/$C3 -> 0.0007500577 | L3: 102 | M3: =L3/$C3 -> 0.002942534 | N3: 0 | O3: =N3/$C3 -> 0 | P3: 26 | Q3: =P3/$C3 -> 0.0007500577 | R3: 0 | S3: =R3/$C3 -> 0 | T3: 0 | U3: =T3/$C3 -> 0 | W3: =V3/$C3 -> 0 | Y3: =X3/$C3 -> 0 | Z3: 55 | AA3: =Z3/$C3 -> 0.0015866605 | AB3: 0 | AC3: =AB3/$C3 -> 0 | AE3: =AD3/$C3 -> 0 | AG3: =AF3/$C3 -> 0 | AI3: =AH3/$C$3 -> 0 | AK3: =AJ3/$C3 -> 0 | AL3: 0 | AM3: =AL3/$C3 -> 0 | AN3: 0 | AO3: =AN3/$C3 -> 0 | AP3: 0 | AQ3: =AP3/$C3 -> 0 | AR3: 3 | AS3: =AR3/$C3 -> 8.6545119e-05 | AU3: =AT3/$C3 -> 0
A4: ERIO AMBE FASTNERS PVT.LTD. Patna Bihar | B4: June 2025 | C4: =D4+F4 -> 40443 | D4: 40119 | E4: =D4/C4 -> 0.99198872 | F4: 324 | G4: =F4/$C4 -> 0.0080112751 | H4: 0 | I4: =H4/$C4 -> 0 | J4: 43 | K4: =J4/$C4 -> 0.0010632248 | L4: 145 | M4: =L4/$C4 -> 0.0035852929 | N4: 0 | O4: =N4/$C4 -> 0 | P4: 48 | Q4: =P4/$C4 -> 0.0011868556 | R4: 0 | S4: =R4/$C4 -> 0 | T4: 0 | U4: =T4/$C4 -> 0 | W4: =V4/$C4 -> 0 | Y4: =X4/$C4 -> 0 | Z4: 49 | AA4: =Z4/$C4 -> 0.0012115817 | AB4: 0 | AC4: =AB4/$C4 -> 0 | AE4: =AD4/$C4 -> 0 | AG4: =AF4/$C4 -> 0 | AI4: =AH4/$C$3 -> 0 | AK4: =AJ4/$C4 -> 0 | AL4: 0 | AM4: =AL4/$C4 -> 0 | AN4: 30 | AO4: =AN4/$C4 -> 0.00074178473 | AP4: 0 | AQ4: =AP4/$C4 -> 0 | AR4: 9 | AS4: =AR4/$C4 -> 0.00022253542 | AU4: =AT4/$C4 -> 0
A5: ERIO AMBE FASTNERS PVT.LTD. Patna Bihar | B5: July 2025 | C5: =D5+F5 -> 64388 | D5: 63682 | E5: =D5/C5 -> 0.98903522 | F5: 706 | G5: =F5/$C5 -> 0.010964776 | H5: 0 | I5: =H5/$C5 -> 0 | J5: 208 | K5: =J5/$C5 -> 0.0032304156 | L5: 198 | M5: =L5/$C5 -> 0.0030751072 | N5: 0 | O5: =N5/$C5 -> 0 | P5: 38 | Q5: =P5/$C5 -> 0.00059017208 | R5: 0 | S5: =R5/$C5 -> 0 | T5: 0 | U5: =T5/$C5 -> 0 | W5: =V5/$C5 -> 0 | Y5: =X5/$C5 -> 0 | Z5: 117 | AA5: =Z5/$C5 -> 0.0018171088 | AB5: 0 | AC5: =AB5/$C5 -> 0 | AE5: =AD5/$C5 -> 0 | AG5: =AF5/$C5 -> 0 | AI5: =AH5/$C$3 -> 0 | AK5: =AJ5/$C5 -> 0 | AL5: 0 | AM5: =AL5/$C5 -> 0 | AN5: 99 | AO5: =AN5/$C5 -> 0.0015375536 | AP5: 0 | AQ5: =AP5/$C5 -> 0 | AR5: 46 | AS5: =AR5/$C5 -> 0.00071441884 | AU5: =AT5/$C5 -> 0
A6: ERIO AMBE FASTNERS PVT.LTD. Patna Bihar | B6: August 2025 | C6: =D6+F6 -> 54536 | D6: 53885 | E6: =D6/C6 -> 0.98806293 | F6: 651 | G6: =F6/$C6 -> 0.011937069 | H6: 0 | I6: =H6/$C6 -> 0 | J6: 120 | K6: =J6/$C6 -> 0.0022003814 | L6: 277 | M6: =L6/$C6 -> 0.0050792137 | N6: 0 | O6: =N6/$C6 -> 0 | P6: 29 | Q6: =P6/$C6 -> 0.00053175884 | R6: 0 | S6: =R6/$C6 -> 0 | T6: 0 | U6: =T6/$C6 -> 0 | W6: =V6/$C6 -> 0 | Y6: =X6/$C6 -> 0 | Z6: 86 | AA6: =Z6/$C6 -> 0.00157694 | AB6: 0 | AC6: =AB6/$C6 -> 0 | AE6: =AD6/$C6 -> 0 | AG6: =AF6/$C6 -> 0 | AI6: =AH6/$C$3 -> 0 | AK6: =AJ6/$C6 -> 0 | AL6: 0 | AM6: =AL6/$C6 -> 0 | AN6: 117 | AO6: =AN6/$C6 -> 0.0021453719 | AP6: 0 | AQ6: =AP6/$C6 -> 0 | AR6: 22 | AS6: =AR6/$C6 -> 0.00040340326 | AU6: =AT6/$C6 -> 0
A7: ERIO AMBE FASTNERS PVT.LTD. Patna Bihar | B7: September 2025 | C7: =D7+F7 -> 13699 | D7: 13660 | E7: =D7/C7 -> 0.99715308 | F7: 39 | G7: =F7/$C7 -> 0.0028469231 | H7: 0 | I7: =H7/$C7 -> 0 | J7: 10 | K7: =J7/$C7 -> 0.00072998029 | L7: 0 | M7: =L7/$C7 -> 0 | N7: 0 | O7: =N7/$C7 -> 0 | P7: 0 | Q7: =P7/$C7 -> 0 | R7: 0 | S7: =R7/$C7 -> 0 | T7: 0 | U7: =T7/$C7 -> 0 | W7: =V7/$C7 -> 0 | Y7: =X7/$C7 -> 0 | Z7: 14 | AA7: =Z7/$C7 -> 0.0010219724 | AB7: 0 | AC7: =AB7/$C7 -> 0 | AE7: =AD7/$C7 -> 0 | AG7: =AF7/$C7 -> 0 | AI7: =AH7/$C$3 -> 0 | AK7: =AJ7/$C7 -> 0 | AL7: 0 | AM7: =AL7/$C7 -> 0 | AN7: 12 | AO7: =AN7/$C7 -> 0.00087597635 | AP7: 0 | AQ7: =AP7/$C7 -> 0 | AR7: 3 | AS7: =AR7/$C7 -> 0.00021899409 | AU7: =AT7/$C7 -> 0
A8: ERIO CALCUTTA SPRINGS LTD. Howrah West Bengal | B8: May 2025 | C8: =D8+F8 -> 15599 | D8: 15520 | E8: =D8/C8 -> 0.99493557 | F8: 79 | G8: =F8/$C8 -> 0.0050644272 | H8: 0 | I8: =H8/$C8 -> 0 | J8: 0 | K8: =J8/$C8 -> 0 | L8: 8 | M8: =L8/$C8 -> 0.00051285339 | N8: 0 | O8: =N8/$C8 -> 0 | P8: 20 | Q8: =P8/$C8 -> 0.0012821335 | R8: 42 | S8: =R8/$C8 -> 0.0026924803 | T8: 0 | U8: =T8/$C8 -> 0 | W8: =V8/$C8 -> 0 | Y8: =X8/$C8 -> 0 | Z8: 0 | AA8: =Z8/$C8 -> 0 | AB8: 0 | AC8: =AB8/$C8 -> 0 | AE8: =AD8/$C8 -> 0 | AG8: =AF8/$C8 -> 0 | AI8: =AH8/$C$3 -> 0 | AK8: =AJ8/$C8 -> 0 | AL8: 9 | AM8: =AL8/$C8 -> 0.00057696006 | AN8: 0 | AO8: =AN8/$C8 -> 0 | AP8: 0 | AQ8: =AP8/$C8 -> 0 | AR8: 0 | AS8: =AR8/$C8 -> 0 | AU8: =AT8/$C8 -> 0
A9: ERIO CALCUTTA SPRINGS LTD. Howrah West Bengal | B9: June 2025 | C9: =D9+F9 -> 85419 | D9: 84700 | E9: =D9/C9 -> 0.99158267 | F9: 719 | G9: =F9/$C9 -> 0.008417331 | H9: 0 | I9: =H9/$C9 -> 0 | J9: 72 | K9: =J9/$C9 -> 0.0008429038 | L9: 110 | M9: =L9/$C9 -> 0.0012877697 | N9: 0 | O9: =N9/$C9 -> 0 | P9: 195 | Q9: =P9/$C9 -> 0.0022828645 | R9: 198 | S9: =R9/$C9 -> 0.0023179855 | T9: 0 | U9: =T9/$C9 -> 0 | W9: =V9/$C9 -> 0 | Y9: =X9/$C9 -> 0 | Z9: 0 | AA9: =Z9/$C9 -> 0 | AB9: 59 | AC9: =AB9/$C9 -> 0.00069071284 | AE9: =AD9/$C9 -> 0 | AG9: =AF9/$C9 -> 0 | AI9: =AH9/$C$3 -> 0 | AK9: =AJ9/$C9 -> 0 | AL9: 17 | AM9: =AL9/$C9 -> 0.00019901895 | AN9: 68 | AO9: =AN9/$C9 -> 0.00079607581 | AP9: 0 | AQ9: =AP9/$C9 -> 0 | AR9: 0 | AS9: =AR9/$C9 -> 0 | AU9: =AT9/$C9 -> 0
A10: ERIO CALCUTTA SPRINGS LTD. Howrah West Bengal | B10: July 2025 | C10: =D10+F10 -> 113463 | D10: 112885 | E10: =D10/C10 -> 0.99490583 | F10: 578 | G10: =F10/$C10 -> 0.0050941717 | H10: 0 | I10: =H10/$C10 -> 0 | J10: 74 | K10: =J10/$C10 -> 0.00065219499 | L10: 101 | M10: =L10/$C10 -> 0.00089015803 | N10: 0 | O10: =N10/$C10 -> 0 | P10: 60 | Q10: =P10/$C10 -> 0.00052880675 | R10: 101 | S10: =R10/$C10 -> 0.00089015803 | T10: 0 | U10: =T10/$C10 -> 0 | W10: =V10/$C10 -> 0 | Y10: =X10/$C10 -> 0 | Z10: 0 | AA10: =Z10/$C10 -> 0 | AB10: 76 | AC10: =AB10/$C10 -> 0.00066982188 | AE10: =AD10/$C10 -> 0 | AG10: =AF10/$C10 -> 0 | AI10: =AH10/$C$3 -> 0 | AK10: =AJ10/$C10 -> 0 | AL10: 40 | AM10: =AL10/$C10 -> 0.00035253783 | AN10: 126 | AO10: =AN10/$C10 -> 0.0011104942 | AP10: 0 | AQ10: =AP10/$C10 -> 0 | AR10: 0 | AS10: =AR10/$C10 -> 0 | AU10: =AT10/$C10 -> 0
A11: ERIO CALCUTTA SPRINGS LTD. Howrah West Bengal | B11: August 2025 | C11: =D11+F11 -> 198328 | D11: 197420 | E11: =D11/C11 -> 0.99542173 | F11: 908 | G11: =F11/$C11 -> 0.0045782744 | H11: 0 | I11: =H11/$C11 -> 0 | J11: 86 | K11: =J11/$C11 -> 0.00043362511 | L11: 173 | M11: =L11/$C11 -> 0.00087229236 | N11: 0 | O11: =N11/$C11 -> 0 | P11: 80 | Q11: =P11/$C11 -> 0.00040337219 | R11: 95 | S11: =R11/$C11 -> 0.00047900448 | T11: 0 | U11: =T11/$C11 -> 0 | W11: =V11/$C11 -> 0 | Y11: =X11/$C11 -> 0 | Z11: 134 | AA11: =Z11/$C11 -> 0.00067564842 | AB11: 0 | AC11: =AB11/$C11 -> 0 | AE11: =AD11/$C11 -> 0 | AG11: =AF11/$C11 -> 0 | AI11: =AH11/$C$3 -> 0 | AK11: =AJ11/$C11 -> 0 | AL11: 35 | AM11: =AL11/$C11 -> 0.00017647533 | AN11: 305 | AO11: =AN11/$C11 -> 0.0015378565 | AP11: 0 | AQ11: =AP11/$C11 -> 0 | AR11: 0 | AS11: =AR11/$C11 -> 0 | AU11: =AT11/$C11 -> 0
A12: ERIO CALCUTTA SPRINGS LTD. Howrah West Bengal | B12: September 2025 | C12: =D12+F12 -> 355915 | D12: 354044 | E12: =D12/C12 -> 0.99474313 | F12: 1871 | G12: =F12/$C12 -> 0.0052568731 | H12: 0 | I12: =H12/$C12 -> 0 | J12: 330 | K12: =J12/$C12 -> 0.00092718767 | L12: 658 | M12: =L12/$C12 -> 0.001848756 | N12: 0 | O12: =N12/$C12 -> 0 | P12: 201 | Q12: =P12/$C12 -> 0.00056474158 | R12: 151 | S12: =R12/$C12 -> 0.0004242586 | T12: 0 | U12: =T12/$C12 -> 0 | W12: =V12/$C12 -> 0 | Y12: =X12/$C12 -> 0 | Z12: 161 | AA12: =Z12/$C12 -> 0.0004523552 | AB12: 0 | AC12: =AB12/$C12 -> 0 | AE12: =AD12/$C12 -> 0 | AG12: =AF12/$C12 -> 0 | AI12: =AH12/$C$3 -> 0 | AK12: =AJ12/$C12 -> 0 | AL12: 12 | AM12: =AL12/$C12 -> 3.3715915e-05 | AN12: 358 | AO12: =AN12/$C12 -> 0.0010058581 | AP12: 0 | AQ12: =AP12/$C12 -> 0 | AR12: 0 | AS12: =AR12/$C12 -> 0 | AU12: =AT12/$C12 -> 0
A13: ERIO CALCUTTA SPRINGS LTD. Howrah West Bengal | B13: October 2025 | C13: =D13+F13 -> 417139 | D13: 414973 | E13: =D13/C13 -> 0.99480749 | F13: 2166 | G13: =F13/$C13 -> 0.0051925138 | H13: 0 | I13: =H13/$C13 -> 0 | J13: 536 | K13: =J13/$C13 -> 0.0012849434 | L13: 423 | M13: =L13/$C13 -> 0.0010140505 | N13: 0 | O13: =N13/$C13 -> 0 | P13: 155 | Q13: =P13/$C13 -> 0.00037157878 | R13: 204 | S13: =R13/$C13 -> 0.00048904562 | T13: 0 | U13: =T13/$C13 -> 0 | W13: =V13/$C13 -> 0 | Y13: =X13/$C13 -> 0 | Z13: 192 | AA13: =Z13/$C13 -> 0.00046027823 | AB13: 10 | AC13: =AB13/$C13 -> 2.3972824e-05 | AE13: =AD13/$C13 -> 0 | AG13: =AF13/$C13 -> 0 | AI13: =AH13/$C$3 -> 0 | AK13: =AJ13/$C13 -> 0 | AL13: 0 | AM13: =AL13/$C13 -> 0 | AN13: 646 | AO13: =AN13/$C13 -> 0.0015486445 | AP13: 0 | AQ13: =AP13/$C13 -> 0 | AR13: 0 | AS13: =AR13/$C13 -> 0 | AU13: =AT13/$C13 -> 0
A14: ERIO CALCUTTA SPRINGS LTD. Howrah West Bengal | B14: Novemeber 2025 | C14: =D14+F14 -> 318458 | D14: 315812 | E14: =D14/C14 -> 0.99169121 | F14: 2646 | G14: =F14/$C14 -> 0.008308788 | H14: 0 | I14: =H14/$C14 -> 0 | J14: 768 | K14: =J14/$C14 -> 0.002411621 | L14: 562 | M14: =L14/$C14 -> 0.0017647539 | N14: 0 | O14: =N14/$C14 -> 0 | P14: 302 | Q14: =P14/$C14 -> 0.00094831972 | R14: 223 | S14: =R14/$C14 -> 0.00070024933 | T14: 0 | U14: =T14/$C14 -> 0 | W14: =V14/$C14 -> 0 | Y14: =X14/$C14 -> 0 | Z14: 107 | AA14: =Z14/$C14 -> 0.00033599407 | AB14: 0 | AC14: =AB14/$C14 -> 0 | AE14: =AD14/$C14 -> 0 | AG14: =AF14/$C14 -> 0 | AI14: =AH14/$C$3 -> 0 | AK14: =AJ14/$C14 -> 0 | AL14: 59 | AM14: =AL14/$C14 -> 0.00018526776 | AN14: 625 | AO14: =AN14/$C14 -> 0.0019625822 | AP14: 0 | AQ14: =AP14/$C14 -> 0 | AR14: 0 | AS14: =AR14/$C14 -> 0 | AU14: =AT14/$C14 -> 0
... A20: ERIO KALIMATA ISPAT (Unit-1) Howrah West Bengal | B20: Novemeber 2025 | C20: =D20+F20 -> 218950 | D20: 216453 | E20: =D20/C20 -> 0.98859557 | F20: 2497 | G20: =F20/$C20 -> 0.01140443 | H20: 568 | I20: =H20/$C20 -> 0.0025941996 | J20: 103 | K20: =J20/$C20 -> 0.00047042704 | L20: 97 | M20: =L20/$C20 -> 0.00044302352 | N20: 0 | O20: =N20/$C20 -> 0 | P20: 483 | Q20: =P20/$C20 -> 0.0022059831 | R20: 250 | S20: =R20/$C20 -> 0.0011418132 | T20: 25 | U20: =T20/$C20 -> 0.00011418132 | W20: =V20/$C20 -> 0 | Y20: =X20/$C20 -> 0 | Z20: 50 | AA20: =Z20/$C20 -> 0.00022836264 | AB20: 0 | AC20: =AB20/$C20 -> 0 | AE20: =AD20/$C20 -> 0 | AG20: =AF20/$C20 -> 0 | AI20: =AH20/$C$3 -> 0 | AK20: =AJ20/$C20 -> 0 | AL20: 0 | AM20: =AL20/$C20 -> 0 | AN20: 715 | AO20: =AN20/$C20 -> 0.0032655858 | AP20: 0 | AQ20: =AP20/$C20 -> 0 | AR20: 206 | AS20: =AR20/$C20 -> 0.00094085408 | AU20: =AT20/$C20 -> 0
A21: ERIO KALIMATA ISPAT (Unit-II) Durgapur West Bengal | B21: September 2025 | C21: =D21+F21 -> 155530 | D21: 153672 | E21: =D21/C21 -> 0.98805375 | F21: 1858 | G21: =F21/$C21 -> 0.011946248 | H21: 0 | I21: =H21/$C21 -> 0 | J21: 54 | K21: =J21/$C21 -> 0.0003471999 | L21: 67 | M21: =L21/$C21 -> 0.00043078506 | N21: 0 | O21: =N21/$C21 -> 0 | P21: 1125 | Q21: =P21/$C21 -> 0.0072333312 | R21: 336 | S21: =R21/$C21 -> 0.0021603549 | T21: 0 | U21: =T21/$C21 -> 0 | W21: =V21/$C21 -> 0 | Y21: =X21/$C21 -> 0 | Z21: 0 | AA21: =Z21/$C21 -> 0 | AB21: 2 | AC21: =AB21/$C21 -> 1.2859255e-05 | AE21: =AD21/$C21 -> 0 | AG21: =AF21/$C21 -> 0 | AI21: =AH21/$C$3 -> 0 | AK21: =AJ21/$C21 -> 0 | AL21: 0 | AM21: =AL21/$C21 -> 0 | AN21: 274 | AO21: =AN21/$C21 -> 0.001761718 | AP21: 0 | AQ21: =AP21/$C21 -> 0 | AR21: 0 | AS21: =AR21/$C21 -> 0 | AT21: 0 | AU21: =AT21/$C21 -> 0
A22: ERIO KALIMATA ISPAT (Unit-II) Durgapur West Bengal | B22: October 2025 | C22: =D22+F22 -> 313842 | D22: 312274 | E22: =D22/C22 -> 0.99500386 | F22: 1568 | G22: =F22/$C22 -> 0.0049961446 | H22: 0 | I22: =H22/$C22 -> 0 | J22: 41 | K22: =J22/$C22 -> 0.00013063898 | L22: 45 | M22: =L22/$C22 -> 0.00014338425 | N22: 0 | O22: =N22/$C22 -> 0 | P22: 740 | Q22: =P22/$C22 -> 0.0023578743 | R22: 541 | S22: =R22/$C22 -> 0.0017237973 | T22: 0 | U22: =T22/$C22 -> 0 | W22: =V22/$C22 -> 0 | Y22: =X22/$C22 -> 0 | Z22: 0 | AA22: =Z22/$C22 -> 0 | AB22: 2 | AC22: =AB22/$C22 -> 6.3726334e-06 | AE22: =AD22/$C22 -> 0 | AG22: =AF22/$C22 -> 0 | AI22: =AH22/$C$3 -> 0 | AK22: =AJ22/$C22 -> 0 | AL22: 0 | AM22: =AL22/$C22 -> 0 | AN22: 195 | AO22: =AN22/$C22 -> 0.00062133175 | AP22: 0 | AQ22: =AP22/$C22 -> 0 | AR22: 0 | AS22: =AR22/$C22 -> 0 | AT22: 4 | AU22: =AT22/$C22 -> 1.2745267e-05
A23: ERIO KALIMATA ISPAT (Unit-II) Durgapur West Bengal | B23: Novemeber 2025 | C23: =D23+F23 -> 356696 | D23: 354982 | E23: =D23/C23 -> 0.99519479 | F23: 1714 | G23: =F23/$C23 -> 0.0048052123 | H23: 0 | I23: =H23/$C23 -> 0 | J23: 4 | K23: =J23/$C23 -> 1.1214031e-05 | L23: 34 | M23: =L23/$C23 -> 9.5319263e-05 | N23: 0 | O23: =N23/$C23 -> 0 | P23: 786 | Q23: =P23/$C23 -> 0.0022035571 | R23: 666 | S23: =R23/$C23 -> 0.0018671362 | T23: 0 | U23: =T23/$C23 -> 0 | W23: =V23/$C23 -> 0 | Y23: =X23/$C23 -> 0 | Z23: 0 | AA23: =Z23/$C23 -> 0 | AB23: 24 | AC23: =AB23/$C23 -> 6.7284186e-05 | AE23: =AD23/$C23 -> 0 | AG23: =AF23/$C23 -> 0 | AI23: =AH23/$C$3 -> 0 | AK23: =AJ23/$C23 -> 0 | AL23: 0 | AM23: =AL23/$C23 -> 0 | AN23: 190 | AO23: =AN23/$C23 -> 0.00053266647 | AP23: 0 | AQ23: =AP23/$C23 -> 0 | AR23: 0 | AS23: =AR23/$C23 -> 0 | AT23: 10 | AU23: =AT23/$C23 -> 2.8035077e-05
A24: ERIO KALIMATA VYAPAAR (Unit-II) Durgapur West Bengal | B24: July 2025 | C24: =D24+F24 -> 257043 | D24: 253874 | E24: =D24/C24 -> 0.98767132 | F24: 3169 | G24: =F24/$C24 -> 0.012328677 | H24: 0 | I24: =H24/$C24 -> 0 | J24: 176 | K24: =J24/$C24 -> 0.00068471034 | L24: 127 | M24: =L24/$C24 -> 0.00049408076 | N24: 0 | O24: =N24/$C24 -> 0 | P24: 1343 | Q24: =P24/$C24 -> 0.0052248067 | R24: 715 | S24: =R24/$C24 -> 0.0027816358 | T24: 0 | U24: =T24/$C24 -> 0 | W24: =V24/$C24 -> 0 | Y24: =X24/$C24 -> 0 | Z24: 360 | AA24: =Z24/$C24 -> 0.0014005439 | AB24: 0 | AC24: =AB24/$C24 -> 0 | AE24: =AD24/$C24 -> 0 | AG24: =AF24/$C24 -> 0 | AI24: =AH24/$C$3 -> 0 | AK24: =AJ24/$C24 -> 0 | AL24: 0 | AM24: =AL24/$C24 -> 0 | AN24: 442 | AO24: =AN24/$C24 -> 0.0017195567 | AP24: 0 | AQ24: =AP24/$C24 -> 0 | AR24: 6 | AS24: =AR24/$C24 -> 2.3342398e-05 | AT24: 0 | AU24: =AT24/$C24 -> 0
A25: ERIO KALIMATA VYAPAAR (Unit-II) Durgapur West Bengal | B25: August 2025 | C25: =D25+F25 -> 500964 | D25: 495090 | E25: =D25/C25 -> 0.98827461 | F25: 5874 | G25: =F25/$C25 -> 0.011725393 | H25: 0 | I25: =H25/$C25 -> 0 | J25: 63 | K25: =J25/$C25 -> 0.00012575754 | L25: 88 | M25: =L25/$C25 -> 0.00017566132 | N25: 0 | O25: =N25/$C25 -> 0 | P25: 2366 | Q25: =P25/$C25 -> 0.0047228943 | R25: 2326 | S25: =R25/$C25 -> 0.0046430482 | T25: 0 | U25: =T25/$C25 -> 0 | W25: =V25/$C25 -> 0 | Y25: =X25/$C25 -> 0 | Z25: 0 | AA25: =Z25/$C25 -> 0 | AB25: 0 | AC25: =AB25/$C25 -> 0 | AE25: =AD25/$C25 -> 0 | AG25: =AF25/$C25 -> 0 | AI25: =AH25/$C$3 -> 0 | AK25: =AJ25/$C25 -> 0 | AL25: 0 | AM25: =AL25/$C25 -> 0 | AN25: 1031 | AO25: =AN25/$C25 -> 0.0020580321 | AP25: 0 | AQ25: =AP25/$C25 -> 0 | AR25: 0 | AS25: =AR25/$C25 -> 0 | AT25: 0 | AU25: =AT25/$C25 -> 0
A26: ERIO KALIMATA VYAPAAR (Unit-II) Durgapur West Bengal | B26: September 2025 | C26: =D26+F26 -> 475451 | D26: 467681 | E26: =D26/C26 -> 0.98365762 | F26: 7770 | G26: =F26/$C26 -> 0.016342378 | H26: 0 | I26: =H26/$C26 -> 0 | J26: 85 | K26: =J26/$C26 -> 0.00017877762 | L26: 106 | M26: =L26/$C26 -> 0.00022294621 | N26: 0 | O26: =N26/$C26 -> 0 | P26: 4909 | Q26: =P26/$C26 -> 0.010324934 | R26: 1256 | S26: =R26/$C26 -> 0.0026417023 | T26: 0 | U26: =T26/$C26 -> 0 | W26: =V26/$C26 -> 0 | Y26: =X26/$C26 -> 0 | Z26: 0 | AA26: =Z26/$C26 -> 0 | AB26: 0 | AC26: =AB26/$C26 -> 0 | AE26: =AD26/$C26 -> 0 | AG26: =AF26/$C26 -> 0 | AI26: =AH26/$C$3 -> 0 | AK26: =AJ26/$C26 -> 0 | AL26: 0 | AM26: =AL26/$C26 -> 0 | AN26: 1414 | AO26: =AN26/$C26 -> 0.0029740184 | AP26: 0 | AQ26: =AP26/$C26 -> 0 | AR26: 0 | AS26: =AR26/$C26 -> 0 | AT26: 0 | AU26: =AT26/$C26 -> 0
A27: ERIO KALIMATA VYAPAAR (Unit-II) Durgapur West Bengal | B27: October 2025 | C27: =D27+F27 -> 376988 | D27: 369610 | E27: =D27/C27 -> 0.98042909 | F27: 7378 | G27: =F27/$C27 -> 0.019570915 | H27: 0 | I27: =H27/$C27 -> 0 | J27: 187 | K27: =J27/$C27 -> 0.00049603701 | L27: 101 | M27: =L27/$C27 -> 0.00026791304 | N27: 0 | O27: =N27/$C27 -> 0 | P27: 3346 | Q27: =P27/$C27 -> 0.0088756141 | R27: 1458 | S27: =R27/$C27 -> 0.0038674971 | T27: 0 | U27: =T27/$C27 -> 0 | W27: =V27/$C27 -> 0 | Y27: =X27/$C27 -> 0 | Z27: 0 | AA27: =Z27/$C27 -> 0 | AB27: 0 | AC27: =AB27/$C27 -> 0 | AE27: =AD27/$C27 -> 0 | AG27: =AF27/$C27 -> 0 | AI27: =AH27/$C$3 -> 0 | AK27: =AJ27/$C27 -> 0 | AL27: 0 | AM27: =AL27/$C27 -> 0 | AN27: 786 | AO27: =AN27/$C27 -> 0.002084947 | AP27: 0 | AQ27: =AP27/$C27 -> 0 | AR27: 1500 | AS27: =AR27/$C27 -> 0.0039789065 | AT27: 0 | AU27: =AT27/$C27 -> 0
A28: ERIO KALIMATA VYAPAAR (Unit-II) Durgapur West Bengal | B28: Novemeber 2025 | C28: =D28+F28 -> 421734 | D28: 416226 | E28: =D28/C28 -> 0.98693963 | F28: 5508 | G28: =F28/$C28 -> 0.013060365 | H28: 0 | I28: =H28/$C28 -> 0 | J28: 71 | K28: =J28/$C28 -> 0.00016835256 | L28: 114 | M28: =L28/$C28 -> 0.00027031257 | N28: 0 | O28: =N28/$C28 -> 0 | P28: 2030 | Q28: =P28/$C28 -> 0.0048134606 | R28: 1817 | S28: =R28/$C28 -> 0.0043084029 | T28: 0 | U28: =T28/$C28 -> 0 | W28: =V28/$C28 -> 0 | Y28: =X28/$C28 -> 0 | Z28: 385 | AA28: =Z28/$C28 -> 0.0009128977 | AB28: 0 | AC28: =AB28/$C28 -> 0 | AE28: =AD28/$C28 -> 0 | AG28: =AF28/$C28 -> 0 | AI28: =AH28/$C$3 -> 0 | AK28: =AJ28/$C28 -> 0 | AL28: 0 | AM28: =AL28/$C28 -> 0 | AN28: 1086 | AO28: =AN28/$C28 -> 0.0025750829 | AP28: 0 | AQ28: =AP28/$C28 -> 0 | AR28: 0 | AS28: =AR28/$C28 -> 0 | AT28: 5 | AU28: =AT28/$C28 -> 1.1855814e-05
A29: ERIO KDS ENGG. PVT. LTD. Howrah West Bengal | B29: June 2025 | C29: =D29+F29 -> 30784 | D29: 30425 | E29: =D29/C29 -> 0.9883381 | F29: 359 | G29: =F29/$C29 -> 0.011661902 | H29: 0 | I29: =H29/$C29 -> 0 | J29: 48 | K29: =J29/$C29 -> 0.0015592516 | L29: 45 | M29: =L29/$C29 -> 0.0014617983 | N29: 0 | O29: =N29/$C29 -> 0 | P29: 43 | Q29: =P29/$C29 -> 0.0013968295 | R29: 197 | S29: =R29/$C29 -> 0.0063994283 | T29: 0 | U29: =T29/$C29 -> 0 | W29: =V29/$C29 -> 0 | Y29: =X29/$C29 -> 0 | Z29: 0 | AA29: =Z29/$C29 -> 0 | AB29: 0 | AC29: =AB29/$C29 -> 0 | AE29: =AD29/$C29 -> 0 | AG29: =AF29/$C29 -> 0 | AI29: =AH29/$C$3 -> 0 | AK29: =AJ29/$C29 -> 0 | AL29: 4 | AM29: =AL29/$C29 -> 0.00012993763 | AN29: 22 | AO29: =AN29/$C29 -> 0.00071465696 | AP29: 0 | AQ29: =AP29/$C29 -> 0 | AR29: 0 | AS29: =AR29/$C29 -> 0 | AU29: =AT29/$C29 -> 0
A30: ERIO KDS ENGG. PVT. LTD. Howrah West Bengal | B30: July 2025 | C30: =D30+F30 -> 49717 | D30: 49025 | E30: =D30/C30 -> 0.98608122 | F30: 692 | G30: =F30/$C30 -> 0.01391878 | H30: 0 | I30: =H30/$C30 -> 0 | J30: 109 | K30: =J30/$C30 -> 0.002192409 | L30: 53 | M30: =L30/$C30 -> 0.0010660338 | N30: 0 | O30: =N30/$C30 -> 0 | P30: 0 | Q30: =P30/$C30 -> 0 | R30: 476 | S30: =R30/$C30 -> 0.0095741899 | T30: 0 | U30: =T30/$C30 -> 0 | W30: =V30/$C30 -> 0 | Y30: =X30/$C30 -> 0 | Z30: 0 | AA30: =Z30/$C30 -> 0 | AB30: 0 | AC30: =AB30/$C30 -> 0 | AE30: =AD30/$C30 -> 0 | AG30: =AF30/$C30 -> 0 | AI30: =AH30/$C$3 -> 0 | AK30: =AJ30/$C30 -> 0 | AL30: 5 | AM30: =AL30/$C30 -> 0.00010056922 | AN30: 49 | AO30: =AN30/$C30 -> 0.00098557837 | AP30: 0 | AQ30: =AP30/$C30 -> 0 | AR30: 0 | AS30: =AR30/$C30 -> 0 | AU30: =AT30/$C30 -> 0
A31: ERIO KDS ENGG. PVT. LTD. Howrah West Bengal | B31: August 2025 | C31: =D31+F31 -> 38729 | D31: 38338 | E31: =D31/C31 -> 0.98990421 | F31: 391 | G31: =F31/$C31 -> 0.010095794 | H31: 0 | I31: =H31/$C31 -> 0 | J31: 83 | K31: =J31/$C31 -> 0.0021430969 | L31: 33 | M31: =L31/$C31 -> 0.00085207467 | N31: 0 | O31: =N31/$C31 -> 0 | P31: 46 | Q31: =P31/$C31 -> 0.0011877405 | R31: 151 | S31: =R31/$C31 -> 0.0038988871 | T31: 0 | U31: =T31/$C31 -> 0 | W31: =V31/$C31 -> 0 | Y31: =X31/$C31 -> 0 | Z31: 0 | AA31: =Z31/$C31 -> 0 | AB31: 0 | AC31: =AB31/$C31 -> 0 | AE31: =AD31/$C31 -> 0 | AG31: =AF31/$C31 -> 0 | AI31: =AH31/$C$3 -> 0 | AK31: =AJ31/$C31 -> 0 | AL31: 0 | AM31: =AL31/$C31 -> 0 | AN31: 78 | AO31: =AN31/$C31 -> 0.0020139947 | AP31: 0 | AQ31: =AP31/$C31 -> 0 | AR31: 0 | AS31: =AR31/$C31 -> 0 | AU31: =AT31/$C31 -> 0
A32: ERIO KRISHNA INFRATECH Jharsuguda Odisha | B32: May 2025 | C32: =D32+F32 -> 101635 | D32: 101200 | E32: =D32/C32 -> 0.99571998 | F32: 435 | G32: =F32/$C32 -> 0.0042800216 | H32: 0 | I32: =H32/$C32 -> 0 | J32: 275 | K32: =J32/$C32 -> 0.0027057608 | L32: 0 | M32: =L32/$C32 -> 0 | N32: 0 | O32: =N32/$C32 -> 0 | P32: 101 | Q32: =P32/$C32 -> 0.00099375215 | R32: 44 | S32: =R32/$C32 -> 0.00043292173 | T32: 0 | U32: =T32/$C32 -> 0 | W32: =V32/$C32 -> 0 | Y32: =X32/$C32 -> 0 | Z32: 0 | AA32: =Z32/$C32 -> 0 | AB32: 0 | AC32: =AB32/$C32 -> 0 | AE32: =AD32/$C32 -> 0 | AG32: =AF32/$C32 -> 0 | AI32: =AH32/$C$3 -> 0 | AK32: =AJ32/$C32 -> 0 | AL32: 15 | AM32: =AL32/$C32 -> 0.00014758695 | AN32: 0 | AO32: =AN32/$C32 -> 0 | AP32: 0 | AQ32: =AP32/$C32 -> 0 | AR32: 0 | AS32: =AR32/$C32 -> 0 | AU32: =AT32/$C32 -> 0
A33: ERIO KRISHNA INFRATECH Jharsuguda Odisha | B33: June 2025 | C33: =D33+F33 -> 142851 | D33: 141702 | E33: =D33/C33 -> 0.99195665 | F33: 1149 | G33: =F33/$C33 -> 0.0080433459 | H33: 0 | I33: =H33/$C33 -> 0 | J33: 757 | K33: =J33/$C33 -> 0.0052992279 | L33: 0 | M33: =L33/$C33 -> 0 | N33: 0 | O33: =N33/$C33 -> 0 | P33: 189 | Q33: =P33/$C33 -> 0.0013230569 | R33: 162 | S33: =R33/$C33 -> 0.0011340488 | T33: 0 | U33: =T33/$C33 -> 0 | W33: =V33/$C33 -> 0 | Y33: =X33/$C33 -> 0 | Z33: 0 | AA33: =Z33/$C33 -> 0 | AB33: 0 | AC33: =AB33/$C33 -> 0 | AE33: =AD33/$C33 -> 0 | AG33: =AF33/$C33 -> 0 | AI33: =AH33/$C$3 -> 0 | AK33: =AJ33/$C33 -> 0 | AL33: 41 | AM33: =AL33/$C33 -> 0.00028701234 | AN33: 0 | AO33: =AN33/$C33 -> 0 | AP33: 0 | AQ33: =AP33/$C33 -> 0 | AR33: 0 | AS33: =AR33/$C33 -> 0 | AU33: =AT33/$C33 -> 0
A34: ERIO KRISHNA INFRATECH Jharsuguda Odisha | B34: July 2025 | C34: =D34+F34 -> 280351 | D34: 277567 | E34: =D34/C34 -> 0.99006959 | F34: 2784 | G34: =F34/$C34 -> 0.0099304087 | H34: 0 | I34: =H34/$C34 -> 0 | J34: 1581 | K34: =J34/$C34 -> 0.0056393592 | L34: 236 | M34: =L34/$C34 -> 0.00084180188 | N34: 0 | O34: =N34/$C34 -> 0 | P34: 425 | Q34: =P34/$C34 -> 0.0015159568 | R34: 321 | S34: =R34/$C34 -> 0.0011449932 | T34: 0 | U34: =T34/$C34 -> 0 | W34: =V34/$C34 -> 0 | Y34: =X34/$C34 -> 0 | Z34: 0 | AA34: =Z34/$C34 -> 0 | AB34: 0 | AC34: =AB34/$C34 -> 0 | AE34: =AD34/$C34 -> 0 | AG34: =AF34/$C34 -> 0 | AI34: =AH34/$C$3 -> 0 | AK34: =AJ34/$C34 -> 0 | AL34: 221 | AM34: =AL34/$C34 -> 0.00078829753 | AN34: 0 | AO34: =AN34/$C34 -> 0 | AP34: 0 | AQ34: =AP34/$C34 -> 0 | AR34: 0 | AS34: =AR34/$C34 -> 0 | AU34: =AT34/$C34 -> 0
A35: ERIO KRISHNA INFRATECH Jharsuguda Odisha | B35: August 2025 | C35: =D35+F35 -> 201251 | D35: 199170 | E35: =D35/C35 -> 0.98965968 | F35: 2081 | G35: =F35/$C35 -> 0.010340321 | H35: 0 | I35: =H35/$C35 -> 0 | J35: 1501 | K35: =J35/$C35 -> 0.007458348 | L35: 184 | M35: =L35/$C35 -> 0.00091428117 | N35: 0 | O35: =N35/$C35 -> 0 | P35: 156 | Q35: =P35/$C35 -> 0.00077515143 | R35: 68 | S35: =R35/$C35 -> 0.00033788652 | T35: 0 | U35: =T35/$C35 -> 0 | W35: =V35/$C35 -> 0 | Y35: =X35/$C35 -> 0 | Z35: 0 | AA35: =Z35/$C35 -> 0 | AB35: 0 | AC35: =AB35/$C35 -> 0 | AE35: =AD35/$C35 -> 0 | AG35: =AF35/$C35 -> 0 | AI35: =AH35/$C$3 -> 0 | AK35: =AJ35/$C35 -> 0 | AL35: 172 | AM35: =AL35/$C35 -> 0.00085465414 | AN35: 0 | AO35: =AN35/$C35 -> 0 | AP35: 0 | AQ35: =AP35/$C35 -> 0 | AR35: 0 | AS35: =AR35/$C35 -> 0 | AU35: =AT35/$C35 -> 0
A36: ERIO KRISHNA INFRATECH Jharsuguda Odisha | B36: September 2025 | C36: =D36+F36 -> 205140 | D36: 203166 | E36: =D36/C36 -> 0.9903773 | F36: 1974 | G36: =F36/$C36 -> 0.0096226967 | H36: 0 | I36: =H36/$C36 -> 0 | J36: 927 | K36: =J36/$C36 -> 0.0045188652 | L36: 271 | M36: =L36/$C36 -> 0.001321049 | N36: 0 | O36: =N36/$C36 -> 0 | P36: 165 | Q36: =P36/$C36 -> 0.00080432875 | R36: 211 | S36: =R36/$C36 -> 0.0010285659 | T36: 0 | U36: =T36/$C36 -> 0 | W36: =V36/$C36 -> 0 | Y36: =X36/$C36 -> 0 | Z36: 0 | AA36: =Z36/$C36 -> 0 | AB36: 0 | AC36: =AB36/$C36 -> 0 | AE36: =AD36/$C36 -> 0 | AG36: =AF36/$C36 -> 0 | AI36: =AH36/$C$3 -> 0 | AK36: =AJ36/$C36 -> 0 | AL36: 90 | AM36: =AL36/$C36 -> 0.00043872477 | AN36: 270 | AO36: =AN36/$C36 -> 0.0013161743 | AP36: 0 | AQ36: =AP36/$C36 -> 0 | AR36: 40 | AS36: =AR36/$C36 -> 0.00019498879 | AU36: =AT36/$C36 -> 0
